2023-12-17 13:03:10,488 - main_logger - INFO - Bot started! Connecting to DB...
2023-12-17 13:03:12,452 - main_logger - INFO - Connected to DB
2023-12-17 13:06:59,754 - main_logger - INFO - Bot started! Connecting to DB...
2023-12-17 13:07:02,032 - main_logger - INFO - Connected to DB
2023-12-17 13:14:24,249 - main_logger - INFO - Bot started! Connecting to DB...
2023-12-17 13:14:26,134 - main_logger - INFO - Connected to DB
2023-12-17 13:25:21,119 - main_logger - INFO - Bot started! Connecting to DB...
2023-12-17 13:25:22,747 - main_logger - INFO - Connected to DB
2023-12-17 13:32:18,498 - clients_logger - DEBUG - {'user_id': 222151854, 'username': 'גוון ויינברגר', 'full_name': 'בדיקה1', 'address': 'בדיקה'}
2023-12-17 13:37:14,053 - main_logger - INFO - Bot started! Connecting to DB...
2023-12-17 13:37:15,971 - main_logger - INFO - Connected to DB
2023-12-17 13:37:58,371 - clients_logger - DEBUG - {'user_id': 222151854, 'username': 'גוון ויינברגר', 'full_name': 'בדיקה1', 'address': 'בדיקה'}
2023-12-17 13:38:10,092 - db_connection_logger - INFO - user tried to add client that is already in the list
2023-12-17 13:38:10,093 - db_connection_logger - ERROR - unable to add client to data base
2023-12-17 13:41:04,789 - main_logger - INFO - Bot started! Connecting to DB...
2023-12-17 13:41:06,180 - main_logger - INFO - Connected to DB
2023-12-17 13:42:32,704 - clients_logger - DEBUG - {'user_id': 222151854, 'username': 'גוון ויינברגר', 'full_name': 'בדיקה3', 'address': 'בדיקה'}
2023-12-17 13:42:42,840 - clients_logger - DEBUG - {'user_id': 222151854, 'username': 'גוון ויינברגר', 'full_name': 'תבדיקה4', 'address': 'בדיקה'}
2023-12-17 13:44:08,811 - main_logger - INFO - Bot started! Connecting to DB...
2023-12-17 13:44:10,692 - main_logger - INFO - Connected to DB
2023-12-17 14:01:18,437 - main_logger - INFO - Bot started! Connecting to DB...
2023-12-17 14:01:20,446 - main_logger - INFO - Connected to DB
2023-12-17 14:01:37,551 - clients_logger - DEBUG - {'user_id': 222151854, 'username': 'גוון ויינברגר', 'full_name': 'בדיקה1', 'address': 'בדיקה'}
2023-12-17 14:01:50,762 - clients_logger - DEBUG - {'user_id': 222151854, 'username': 'גוון ויינברגר', 'full_name': 'בדיקה2', 'address': 'בדיקה'}
2023-12-17 14:02:16,679 - clients_logger - DEBUG - {'user_id': 222151854, 'username': 'גוון ויינברגר', 'full_name': 'תבדיקה3', 'address': 'בדיקה'}
2023-12-17 14:04:17,045 - main_logger - INFO - Bot started! Connecting to DB...
2023-12-17 14:04:19,444 - main_logger - INFO - Connected to DB
2023-12-17 14:09:52,831 - main_logger - INFO - Bot started! Connecting to DB...
2023-12-17 14:09:55,119 - main_logger - INFO - Connected to DB
2023-12-17 14:13:08,259 - main_logger - INFO - Bot started! Connecting to DB...
2023-12-17 14:13:10,285 - main_logger - INFO - Connected to DB
2023-12-17 14:15:45,733 - main_logger - INFO - Bot started! Connecting to DB...
2023-12-17 14:15:47,787 - main_logger - INFO - Connected to DB
2023-12-17 14:16:21,994 - clients_logger - DEBUG - {'user_id': 222151854, 'username': 'גוון ויינברגר', 'full_name': 'גוון', 'address': 'בדיקה1'}
2023-12-17 14:16:51,077 - clients_logger - DEBUG - {'user_id': 222151854, 'username': 'גוון ויינברגר', 'full_name': 'בדיקה1', 'address': 'בדיקה2'}
2023-12-17 14:21:44,854 - main_logger - INFO - Bot started! Connecting to DB...
2023-12-17 14:21:46,529 - main_logger - INFO - Connected to DB
2023-12-17 14:21:58,130 - clients_logger - DEBUG - {'user_id': 222151854, 'username': 'גוון ויינברגר', 'full_name': 'גוון', 'address': 'ויינברגר'}
2023-12-17 14:22:49,775 - clients_logger - ERROR - can't show buttons with names of client to delete
Traceback (most recent call last):
  File "c:\Users\User\OneDrive\שולחן העבודה\My assistant project\my_assistant\clients.py", line 258, in next_page
    await update.callback_query.message.reply_text(reply_markup=reply_markup, parse_mode='Markdown')
          ^^^^^^^^^^^^^^^^^^^^^^^^^^^^^^^^^^^^^^^^^^^^^^^^^^^^^^^^^^^^^^^^^^^^^^^^^^^^^^^^^^^^^^^^^^
TypeError: Message.reply_text() missing 1 required positional argument: 'text'
2023-12-17 14:24:01,160 - main_logger - INFO - Bot started! Connecting to DB...
2023-12-17 14:24:02,988 - main_logger - INFO - Connected to DB
2023-12-17 14:24:10,550 - clients_logger - ERROR - can't show buttons with names of client to delete
Traceback (most recent call last):
  File "c:\Users\User\OneDrive\שולחן העבודה\My assistant project\my_assistant\clients.py", line 258, in next_page
    await update.callback_query.message.reply_text("", reply_markup=reply_markup, parse_mode='Markdown')
  File "C:\Users\User\OneDrive\שולחן העבודה\My assistant project\venv\Lib\site-packages\telegram\_message.py", line 1094, in reply_text
    return await self.get_bot().send_message(
           ^^^^^^^^^^^^^^^^^^^^^^^^^^^^^^^^^^
  File "C:\Users\User\OneDrive\שולחן העבודה\My assistant project\venv\Lib\site-packages\telegram\ext\_extbot.py", line 2624, in send_message
    return await super().send_message(
           ^^^^^^^^^^^^^^^^^^^^^^^^^^^
  File "C:\Users\User\OneDrive\שולחן העבודה\My assistant project\venv\Lib\site-packages\telegram\_bot.py", line 525, in decorator
    result = await func(self, *args, **kwargs)  # skipcq: PYL-E1102
             ^^^^^^^^^^^^^^^^^^^^^^^^^^^^^^^^^
  File "C:\Users\User\OneDrive\שולחן העבודה\My assistant project\venv\Lib\site-packages\telegram\_bot.py", line 846, in send_message
    return await self._send_message(
           ^^^^^^^^^^^^^^^^^^^^^^^^^
  File "C:\Users\User\OneDrive\שולחן העבודה\My assistant project\venv\Lib\site-packages\telegram\ext\_extbot.py", line 522, in _send_message
    result = await super()._send_message(
             ^^^^^^^^^^^^^^^^^^^^^^^^^^^^
  File "C:\Users\User\OneDrive\שולחן העבודה\My assistant project\venv\Lib\site-packages\telegram\_bot.py", line 703, in _send_message
    result = await self._post(
             ^^^^^^^^^^^^^^^^^
  File "C:\Users\User\OneDrive\שולחן העבודה\My assistant project\venv\Lib\site-packages\telegram\_bot.py", line 613, in _post
    return await self._do_post(
           ^^^^^^^^^^^^^^^^^^^^
  File "C:\Users\User\OneDrive\שולחן העבודה\My assistant project\venv\Lib\site-packages\telegram\ext\_extbot.py", line 340, in _do_post
    return await super()._do_post(
           ^^^^^^^^^^^^^^^^^^^^^^^
  File "C:\Users\User\OneDrive\שולחן העבודה\My assistant project\venv\Lib\site-packages\telegram\_bot.py", line 641, in _do_post
    return await request.post(
           ^^^^^^^^^^^^^^^^^^^
  File "C:\Users\User\OneDrive\שולחן העבודה\My assistant project\venv\Lib\site-packages\telegram\request\_baserequest.py", line 200, in post
    result = await self._request_wrapper(
             ^^^^^^^^^^^^^^^^^^^^^^^^^^^^
  File "C:\Users\User\OneDrive\שולחן העבודה\My assistant project\venv\Lib\site-packages\telegram\request\_baserequest.py", line 379, in _request_wrapper
    raise BadRequest(message)
telegram.error.BadRequest: Message text is empty
2023-12-17 14:24:53,645 - main_logger - INFO - Bot started! Connecting to DB...
2023-12-17 14:24:55,216 - main_logger - INFO - Connected to DB
2023-12-17 14:26:33,536 - clients_logger - DEBUG - {'user_id': 222151854, 'username': 'גוון ויינברגר', 'full_name': 'רומי מזרחי', 'address': 'זום'}
2023-12-17 14:29:22,414 - main_logger - INFO - Bot started! Connecting to DB...
2023-12-17 14:29:24,273 - main_logger - INFO - Connected to DB
2023-12-17 14:36:02,061 - main_logger - INFO - Bot started! Connecting to DB...
2023-12-17 14:36:03,818 - main_logger - INFO - Connected to DB
2023-12-17 14:41:03,549 - main_logger - INFO - Bot started! Connecting to DB...
2023-12-17 14:41:05,174 - main_logger - INFO - Connected to DB
2023-12-17 14:41:33,681 - clients_logger - ERROR - The parameter `inline_keyboard` should be a sequence of sequences of InlineKeyboardButtons
Traceback (most recent call last):
  File "c:\Users\User\OneDrive\שולחן העבודה\My assistant project\my_assistant\clients.py", line 129, in show_clients_callback
    reply_markup = InlineKeyboardMarkup(keyboard)
                   ^^^^^^^^^^^^^^^^^^^^^^^^^^^^^^
  File "C:\Users\User\OneDrive\שולחן העבודה\My assistant project\venv\Lib\site-packages\telegram\_inline\inlinekeyboardmarkup.py", line 79, in __init__
    raise ValueError(
ValueError: The parameter `inline_keyboard` should be a sequence of sequences of InlineKeyboardButtons
2023-12-17 14:42:14,116 - clients_logger - ERROR - The parameter `inline_keyboard` should be a sequence of sequences of InlineKeyboardButtons
Traceback (most recent call last):
  File "c:\Users\User\OneDrive\שולחן העבודה\My assistant project\my_assistant\clients.py", line 129, in show_clients_callback
    reply_markup = InlineKeyboardMarkup(keyboard)
                   ^^^^^^^^^^^^^^^^^^^^^^^^^^^^^^
  File "C:\Users\User\OneDrive\שולחן העבודה\My assistant project\venv\Lib\site-packages\telegram\_inline\inlinekeyboardmarkup.py", line 79, in __init__
    raise ValueError(
ValueError: The parameter `inline_keyboard` should be a sequence of sequences of InlineKeyboardButtons
2023-12-17 14:43:31,693 - main_logger - INFO - Bot started! Connecting to DB...
2023-12-17 14:43:33,566 - main_logger - INFO - Connected to DB
2023-12-18 10:35:44,035 - main_logger - INFO - Bot started! Connecting to DB...
2023-12-18 10:35:45,873 - main_logger - INFO - Connected to DB
2023-12-18 10:58:02,952 - main_logger - INFO - Bot started! Connecting to DB...
2023-12-18 10:58:04,880 - main_logger - INFO - Connected to DB
2023-12-18 10:59:23,953 - main_logger - INFO - Bot started! Connecting to DB...
2023-12-18 10:59:25,727 - main_logger - INFO - Connected to DB
2023-12-18 11:30:34,999 - main_logger - INFO - Bot started! Connecting to DB...
2023-12-18 11:30:36,729 - main_logger - INFO - Connected to DB
2023-12-18 11:30:50,622 - clients_logger - DEBUG - [{'id': 26, 'full_name': 'אגם כהן', 'address': 'זום', 'debt': 0, 'create_time': datetime.datetime(2023, 12, 14, 21, 57, 13), 'user_id': '222151854', 'username': 'גוון ויינברגר'}, {'id': 49, 'full_name': 'אלכסנדרה אהרון', 'address': 'זום', 'debt': 120, 'create_time': datetime.datetime(2023, 12, 17, 10, 26, 5), 'user_id': '222151854', 'username': 'גוון ויינברגר'}, {'id': 30, 'full_name': 'אסף בובק', 'address': 'זום', 'debt': 100, 'create_time': datetime.datetime(2023, 12, 16, 19, 31, 58), 'user_id': '222151854', 'username': 'גוון ויינברגר'}, {'id': 31, 'full_name': 'דביר סולמי', 'address': 'זום', 'debt': 0, 'create_time': datetime.datetime(2023, 12, 16, 19, 32, 56), 'user_id': '222151854', 'username': 'גוון ויינברגר'}, {'id': 37, 'full_name': 'דרור מזרחי', 'address': 'זום', 'debt': 0, 'create_time': datetime.datetime(2023, 12, 16, 19, 38, 13), 'user_id': '222151854', 'username': 'גוון ויינברגר'}, {'id': 36, 'full_name': 'נדב כהן', 'address': 'הדקל 22 לפיד', 'debt': 0, 'create_time': datetime.datetime(2023, 12, 16, 19, 37, 34), 'user_id': '222151854', 'username': 'גוון ויינברגר'}, {'id': 33, 'full_name': 'נועם אפשטיין', 'address': 'הזית 74 לפיד', 'debt': 0, 'create_time': datetime.datetime(2023, 12, 16, 19, 35, 27), 'user_id': '222151854', 'username': 'גוון ויינברגר'}, {'id': 29, 'full_name': 'עדי לוי', 'address': 'שבטי ישראל 17 מודיעין', 'debt': 0, 'create_time': datetime.datetime(2023, 12, 16, 19, 31, 44), 'user_id': '222151854', 'username': 'גוון ויינברגר'}, {'id': 24, 'full_name': 'עדי עזרא', 'address': 'זום', 'debt': 0, 'create_time': datetime.datetime(2023, 12, 14, 16, 52, 45), 'user_id': '222151854', 'username': 'גוון ויינברגר'}, {'id': 32, 'full_name': 'עומרי נוף', 'address': 'זום', 'debt': 0, 'create_time': datetime.datetime(2023, 12, 16, 19, 34, 48), 'user_id': '222151854', 'username': 'גוון ויינברגר'}, {'id': 38, 'full_name': 'עופרי עזרא', 'address': 'זום', 'debt': 0, 'create_time': datetime.datetime(2023, 12, 17, 9, 53, 24), 'user_id': '222151854', 'username': 'גוון ויינברגר'}, {'id': 78, 'full_name': 'רומי מזרחי', 'address': 'זום', 'debt': 0, 'create_time': datetime.datetime(2023, 12, 17, 12, 26, 7), 'user_id': '222151854', 'username': 'גוון ויינברגר'}, {'id': 34, 'full_name': 'שירה זנטי', 'address': 'גורדון 23 נווה שאנן חיפה', 'debt': 0, 'create_time': datetime.datetime(2023, 12, 16, 19, 36, 30), 'user_id': '222151854', 'username': 'גוון ויינברגר'}]
2023-12-18 11:40:06,818 - main_logger - INFO - Bot started! Connecting to DB...
2023-12-18 11:40:08,182 - main_logger - INFO - Connected to DB
2023-12-18 11:40:58,008 - main_logger - INFO - Bot started! Connecting to DB...
2023-12-18 11:40:59,238 - main_logger - INFO - Connected to DB
2023-12-18 13:10:17,173 - main_logger - INFO - Bot started! Connecting to DB...
2023-12-18 13:10:19,016 - main_logger - INFO - Connected to DB
2023-12-18 13:10:51,047 - main_logger - INFO - Bot started! Connecting to DB...
2023-12-18 13:10:52,696 - main_logger - INFO - Connected to DB
2023-12-18 13:14:15,856 - main_logger - INFO - Bot started! Connecting to DB...
2023-12-18 13:14:18,050 - main_logger - INFO - Connected to DB
2023-12-18 13:14:38,329 - db_connection_logger - ERROR - unable to add debt to the client in the data base
2023-12-18 13:14:38,340 - clients_logger - ERROR - 1054 (42S22): Unknown column 'client_id' in 'where clause'
Traceback (most recent call last):
  File "C:\Users\User\OneDrive\שולחן העבודה\My assistant project\venv\Lib\site-packages\mysql\connector\connection_cext.py", line 639, in cmd_query
    self._cmysql.query(
_mysql_connector.MySQLInterfaceError: Unknown column 'client_id' in 'where clause'

The above exception was the direct cause of the following exception:

Traceback (most recent call last):
  File "c:\Users\User\OneDrive\שולחן העבודה\My assistant project\my_assistant\clients.py", line 372, in add_debt
    add_debt_to_db(client_id=client_id, user_id=user_id, debt_to_add=debt)
  File "c:\Users\User\OneDrive\שולחן העבודה\My assistant project\my_assistant\db_connection.py", line 118, in add_debt_to_db
    db_cursor.execute(sql_add_debt, (debt_to_add, client_id, user_id))
  File "C:\Users\User\OneDrive\שולחן העבודה\My assistant project\venv\Lib\site-packages\mysql\connector\cursor_cext.py", line 330, in execute
    result = self._cnx.cmd_query(
             ^^^^^^^^^^^^^^^^^^^^
  File "C:\Users\User\OneDrive\שולחן העבודה\My assistant project\venv\Lib\site-packages\mysql\connector\opentelemetry\context_propagation.py", line 77, in wrapper
    return method(cnx, *args, **kwargs)
           ^^^^^^^^^^^^^^^^^^^^^^^^^^^^
  File "C:\Users\User\OneDrive\שולחן העבודה\My assistant project\venv\Lib\site-packages\mysql\connector\connection_cext.py", line 647, in cmd_query
    raise get_mysql_exception(
mysql.connector.errors.ProgrammingError: 1054 (42S22): Unknown column 'client_id' in 'where clause'
2023-12-18 13:19:29,371 - main_logger - INFO - Bot started! Connecting to DB...
2023-12-18 13:19:30,746 - main_logger - INFO - Connected to DB
2023-12-18 13:19:49,998 - clients_logger - DEBUG - 49
2023-12-18 13:19:50,009 - clients_logger - DEBUG - {'id': 49, 'full_name': 'אלכסנדרה אהרון', 'address': 'זום', 'debt': 0, 'create_time': datetime.datetime(2023, 12, 17, 10, 26, 5), 'user_id': '222151854', 'username': 'גוון ויינברגר'}
2023-12-18 13:19:50,161 - db_connection_logger - ERROR - unable to add debt to the client in the data base
2023-12-18 13:19:50,169 - clients_logger - ERROR - 1054 (42S22): Unknown column 'client_id' in 'where clause'
Traceback (most recent call last):
  File "C:\Users\User\OneDrive\שולחן העבודה\My assistant project\venv\Lib\site-packages\mysql\connector\connection_cext.py", line 639, in cmd_query
    self._cmysql.query(
_mysql_connector.MySQLInterfaceError: Unknown column 'client_id' in 'where clause'

The above exception was the direct cause of the following exception:

Traceback (most recent call last):
  File "c:\Users\User\OneDrive\שולחן העבודה\My assistant project\my_assistant\clients.py", line 376, in add_debt
    add_debt_to_db(client_id=client_id, user_id=user_id, debt_to_add=debt)
  File "c:\Users\User\OneDrive\שולחן העבודה\My assistant project\my_assistant\db_connection.py", line 118, in add_debt_to_db
    db_cursor.execute(sql_add_debt, (debt_to_add, client_id, user_id))
  File "C:\Users\User\OneDrive\שולחן העבודה\My assistant project\venv\Lib\site-packages\mysql\connector\cursor_cext.py", line 330, in execute
    result = self._cnx.cmd_query(
             ^^^^^^^^^^^^^^^^^^^^
  File "C:\Users\User\OneDrive\שולחן העבודה\My assistant project\venv\Lib\site-packages\mysql\connector\opentelemetry\context_propagation.py", line 77, in wrapper
    return method(cnx, *args, **kwargs)
           ^^^^^^^^^^^^^^^^^^^^^^^^^^^^
  File "C:\Users\User\OneDrive\שולחן העבודה\My assistant project\venv\Lib\site-packages\mysql\connector\connection_cext.py", line 647, in cmd_query
    raise get_mysql_exception(
mysql.connector.errors.ProgrammingError: 1054 (42S22): Unknown column 'client_id' in 'where clause'
2023-12-18 13:22:15,105 - main_logger - INFO - Bot started! Connecting to DB...
2023-12-18 13:22:16,819 - main_logger - INFO - Connected to DB
2023-12-18 13:22:39,282 - clients_logger - DEBUG - 49
2023-12-18 13:22:39,283 - clients_logger - DEBUG - {'id': 49, 'full_name': 'אלכסנדרה אהרון', 'address': 'זום', 'debt': 0, 'create_time': datetime.datetime(2023, 12, 17, 10, 26, 5), 'user_id': '222151854', 'username': 'גוון ויינברגר'}
2023-12-18 13:23:15,658 - clients_logger - DEBUG - 32
2023-12-18 13:23:15,660 - clients_logger - DEBUG - {'id': 32, 'full_name': 'עומרי נוף', 'address': 'זום', 'debt': 0, 'create_time': datetime.datetime(2023, 12, 16, 19, 34, 48), 'user_id': '222151854', 'username': 'גוון ויינברגר'}
2023-12-18 13:23:28,533 - clients_logger - DEBUG - 49
2023-12-18 13:23:28,535 - clients_logger - DEBUG - {'id': 49, 'full_name': 'אלכסנדרה אהרון', 'address': 'זום', 'debt': 120, 'create_time': datetime.datetime(2023, 12, 17, 10, 26, 5), 'user_id': '222151854', 'username': 'גוון ויינברגר'}
2023-12-18 13:25:02,091 - main_logger - INFO - Bot started! Connecting to DB...
2023-12-18 13:25:03,987 - main_logger - INFO - Connected to DB
2023-12-18 13:27:11,572 - main_logger - INFO - Bot started! Connecting to DB...
2023-12-18 13:27:13,297 - main_logger - INFO - Connected to DB
2023-12-18 14:54:18,586 - main_logger - INFO - Bot started! Connecting to DB...
2023-12-18 14:54:20,456 - main_logger - INFO - Connected to DB
2023-12-18 14:54:44,595 - clients_logger - ERROR - name 'client_name' is not defined
Traceback (most recent call last):
  File "c:\Users\User\OneDrive\שולחן העבודה\My assistant project\my_assistant\clients.py", line 459, in ask_amount_to_delete
    await update.message.reply_text(f'*ללקוח/ה {client_name} יש חוב של {client_debt}.*\n בחר את הפעולה הרצוייה או לחץ /cancel לביטול',
                                                ^^^^^^^^^^^
NameError: name 'client_name' is not defined. Did you mean: 'client_number'?
2023-12-18 14:55:43,942 - main_logger - INFO - Bot started! Connecting to DB...
2023-12-18 14:55:45,636 - main_logger - INFO - Connected to DB
2023-12-18 14:56:01,469 - db_connection_logger - ERROR - unable to delete debt to the client in the data base
2023-12-18 14:56:01,479 - clients_logger - ERROR - name 'debt_to_add' is not defined
Traceback (most recent call last):
  File "c:\Users\User\OneDrive\שולחן העבודה\My assistant project\my_assistant\clients.py", line 488, in delete_all_debt
    delete_debt_from_db(
  File "c:\Users\User\OneDrive\שולחן העבודה\My assistant project\my_assistant\db_connection.py", line 134, in delete_debt_from_db
    db_cursor.execute(sql_delete_debt, (debt_to_add, client_id, user_id))
                                        ^^^^^^^^^^^
NameError: name 'debt_to_add' is not defined
2023-12-18 14:56:38,745 - main_logger - INFO - Bot started! Connecting to DB...
2023-12-18 14:56:40,007 - main_logger - INFO - Connected to DB
2023-12-18 18:16:28,300 - main_logger - INFO - Bot started! Connecting to DB...
2023-12-18 18:16:31,598 - main_logger - INFO - Connected to DB
2023-12-18 18:35:12,612 - main_logger - INFO - Bot started! Connecting to DB...
2023-12-18 18:35:14,330 - main_logger - INFO - Connected to DB
2023-12-18 18:38:50,323 - clients_logger - ERROR - list index out of range
Traceback (most recent call last):
  File "c:\Users\User\OneDrive\שולחן העבודה\My assistant project\my_assistant\clients.py", line 375, in add_debt
    client_id = (clients_list[client_number_to_add_debt])["id"]
                 ~~~~~~~~~~~~^^^^^^^^^^^^^^^^^^^^^^^^^^^
IndexError: list index out of range
2023-12-18 18:42:08,714 - main_logger - INFO - Bot started! Connecting to DB...
2023-12-18 18:42:10,387 - main_logger - INFO - Connected to DB
2023-12-18 19:10:39,554 - main_logger - INFO - Bot started! Connecting to DB...
2023-12-18 19:10:41,147 - main_logger - INFO - Connected to DB
2023-12-18 19:59:03,614 - main_logger - INFO - Bot started! Connecting to DB...
2023-12-18 19:59:05,236 - main_logger - INFO - Connected to DB
2023-12-19 09:27:56,173 - main_logger - INFO - Bot started! Connecting to DB...
2023-12-19 09:27:58,263 - main_logger - INFO - Connected to DB
2023-12-19 09:39:09,338 - main_logger - INFO - Bot started! Connecting to DB...
2023-12-19 09:39:11,237 - main_logger - INFO - Connected to DB
2023-12-19 10:01:21,439 - main_logger - INFO - Bot started! Connecting to DB...
2023-12-19 10:01:23,583 - main_logger - INFO - Connected to DB
2023-12-19 10:02:41,181 - db_connection_logger - INFO - the user tried to add client that is already exists
2023-12-19 10:03:42,421 - main_logger - INFO - Bot started! Connecting to DB...
2023-12-19 10:03:44,258 - main_logger - INFO - Connected to DB
2023-12-19 10:10:39,820 - main_logger - INFO - Bot started! Connecting to DB...
2023-12-19 10:10:41,570 - main_logger - INFO - Connected to DB
2023-12-19 10:10:54,942 - clients_logger - DEBUG - keyError happens: 'address'
2023-12-19 10:17:11,078 - main_logger - INFO - Bot started! Connecting to DB...
2023-12-19 10:17:12,791 - main_logger - INFO - Connected to DB
2023-12-19 10:17:29,382 - db_connection_logger - INFO - clients details not full!
2023-12-19 10:21:35,036 - main_logger - INFO - Bot started! Connecting to DB...
2023-12-19 10:21:36,976 - main_logger - INFO - Connected to DB
2023-12-19 10:21:50,156 - clients_logger - DEBUG - key error:'לא כל פרטי הלקוח מלאים, נא השלם את הפרטים החסרים.'
2023-12-19 10:26:05,996 - main_logger - INFO - Bot started! Connecting to DB...
2023-12-19 10:26:07,791 - main_logger - INFO - Connected to DB
2023-12-19 10:26:25,444 - db_connection_logger - INFO - clients details are not full.
2023-12-19 10:27:27,088 - main_logger - INFO - Bot started! Connecting to DB...
2023-12-19 10:27:28,876 - main_logger - INFO - Connected to DB
2023-12-19 10:31:19,358 - main_logger - INFO - Bot started! Connecting to DB...
2023-12-19 10:31:21,345 - main_logger - INFO - Connected to DB
2023-12-19 10:31:30,622 - db_connection_logger - INFO - clients details are not full.
2023-12-19 10:31:30,624 - clients_logger - DEBUG - 'לא כל פרטי הלקוח מלאים, נא השלם את הפרטים החסרים.'
2023-12-19 10:32:34,363 - main_logger - INFO - Bot started! Connecting to DB...
2023-12-19 10:32:36,087 - main_logger - INFO - Connected to DB
2023-12-19 10:32:54,632 - db_connection_logger - INFO - clients details are not full.
2023-12-19 10:32:54,633 - clients_logger - DEBUG - 'לא כל פרטי הלקוח מלאים, נא השלם את הפרטים החסרים.'
2023-12-19 10:33:36,398 - main_logger - INFO - Bot started! Connecting to DB...
2023-12-19 10:33:38,054 - main_logger - INFO - Connected to DB
2023-12-19 10:33:44,896 - db_connection_logger - INFO - clients details are not full.
2023-12-19 10:35:28,438 - main_logger - INFO - Bot started! Connecting to DB...
2023-12-19 10:35:30,267 - main_logger - INFO - Connected to DB
2023-12-19 10:35:44,123 - db_connection_logger - INFO - clients details are not full.
2023-12-19 10:36:17,227 - main_logger - INFO - Bot started! Connecting to DB...
2023-12-19 10:36:18,758 - main_logger - INFO - Connected to DB
2023-12-19 10:36:24,050 - db_connection_logger - INFO - clients details are not full.
2023-12-19 10:36:37,411 - main_logger - INFO - Bot started! Connecting to DB...
2023-12-19 10:36:39,097 - main_logger - INFO - Connected to DB
2023-12-19 10:36:42,983 - db_connection_logger - INFO - clients details are not full.
2023-12-19 10:36:42,986 - clients_logger - INFO - {}
2023-12-19 10:37:19,889 - main_logger - INFO - Bot started! Connecting to DB...
2023-12-19 10:37:21,440 - main_logger - INFO - Connected to DB
2023-12-19 10:37:28,694 - db_connection_logger - INFO - clients details are not full.
2023-12-19 10:40:24,794 - db_connection_logger - INFO - clients details are not full.
2023-12-19 10:40:56,416 - main_logger - INFO - Bot started! Connecting to DB...
2023-12-19 10:40:57,968 - main_logger - INFO - Connected to DB
2023-12-19 10:41:08,413 - db_connection_logger - INFO - the user tried to add client that is already exists
2023-12-19 11:08:59,069 - main_logger - INFO - Bot started! Connecting to DB...
2023-12-19 11:09:01,547 - main_logger - INFO - Connected to DB
2023-12-19 11:10:58,444 - main_logger - INFO - Bot started! Connecting to DB...
2023-12-19 11:11:00,541 - main_logger - INFO - Connected to DB
2023-12-19 11:44:39,098 - main_logger - INFO - Bot started! Connecting to DB...
2023-12-19 11:44:40,631 - main_logger - INFO - Connected to DB
2023-12-19 11:49:19,321 - main_logger - INFO - Bot started! Connecting to DB...
2023-12-19 11:49:21,216 - main_logger - INFO - Connected to DB
2023-12-19 11:52:07,582 - main_logger - INFO - Bot started! Connecting to DB...
2023-12-19 11:52:09,545 - main_logger - INFO - Connected to DB
2023-12-19 12:06:57,142 - main_logger - INFO - Bot started! Connecting to DB...
2023-12-19 12:06:59,021 - main_logger - INFO - Connected to DB
2023-12-19 12:08:29,015 - clients_logger - ERROR - the user send something that cannot be converted to int
Traceback (most recent call last):
  File "c:\Users\User\OneDrive\שולחן העבודה\My assistant project\my_assistant\clients.py", line 515, in delete_part_debt
    debt_to_delete = int(update.message.text)
                     ^^^^^^^^^^^^^^^^^^^^^^^^
ValueError: invalid literal for int() with base 10: '6כק'
2023-12-19 12:13:31,005 - main_logger - INFO - Bot started! Connecting to DB...
2023-12-19 12:13:32,901 - main_logger - INFO - Connected to DB
2023-12-19 12:13:50,759 - clients_logger - ERROR - the user send something that cannot be converted to int
Traceback (most recent call last):
  File "c:\Users\User\OneDrive\שולחן העבודה\My assistant project\my_assistant\clients.py", line 515, in delete_part_debt
    debt_to_delete = int(update.message.text)
                     ^^^^^^^^^^^^^^^^^^^^^^^^
ValueError: invalid literal for int() with base 10: '15חי'
2023-12-19 12:19:50,262 - main_logger - INFO - Bot started! Connecting to DB...
2023-12-19 12:19:52,158 - main_logger - INFO - Connected to DB
2023-12-19 12:20:06,952 - clients_logger - ERROR - user send client number to ass debt that cannot be converted to int
Traceback (most recent call last):
  File "c:\Users\User\OneDrive\שולחן העבודה\My assistant project\my_assistant\clients.py", line 351, in debt_amount_to_add
    client_number_to_add_debt = int(update.message.text) - 1
                                ^^^^^^^^^^^^^^^^^^^^^^^^
ValueError: invalid literal for int() with base 10: 'g6'
2023-12-19 12:24:55,231 - main_logger - INFO - Bot started! Connecting to DB...
2023-12-19 12:24:57,002 - main_logger - INFO - Connected to DB
2023-12-19 12:25:07,714 - clients_logger - ERROR - user send client number to ass debt that cannot be converted to int
Traceback (most recent call last):
  File "c:\Users\User\OneDrive\שולחן העבודה\My assistant project\my_assistant\clients.py", line 351, in debt_amount_to_add
    client_number_to_add_debt = int(update.message.text) - 1
                                ^^^^^^^^^^^^^^^^^^^^^^^^
ValueError: invalid literal for int() with base 10: 'g6'
2023-12-19 12:25:42,901 - clients_logger - ERROR - list index out of range
Traceback (most recent call last):
  File "c:\Users\User\OneDrive\שולחן העבודה\My assistant project\my_assistant\clients.py", line 373, in add_debt
    client_id = (clients_list[client_number_to_add_debt])["id"]
                 ~~~~~~~~~~~~^^^^^^^^^^^^^^^^^^^^^^^^^^^
IndexError: list index out of range
2023-12-19 12:36:16,140 - main_logger - INFO - Bot started! Connecting to DB...
2023-12-19 12:36:17,970 - main_logger - INFO - Connected to DB
2023-12-19 12:38:14,832 - main_logger - INFO - Bot started! Connecting to DB...
2023-12-19 12:38:16,655 - main_logger - INFO - Connected to DB
2023-12-19 12:43:58,006 - main_logger - INFO - Bot started! Connecting to DB...
2023-12-19 12:43:59,901 - main_logger - INFO - Connected to DB
2023-12-19 12:45:17,130 - main_logger - INFO - Bot started! Connecting to DB...
2023-12-19 12:45:19,342 - main_logger - INFO - Connected to DB
2023-12-19 12:47:13,243 - clients_logger - ERROR - user send number that is bigger than the clients list length
Traceback (most recent call last):
  File "c:\Users\User\OneDrive\שולחן העבודה\My assistant project\my_assistant\clients.py", line 360, in debt_amount_to_add
    raise IndexOfClientIsTooBig()
exceptions.IndexOfClientIsTooBig: הקלדת מספר גדול מידיי שלא נמצא ברשימת הלקוחות, אנא הקלד מספר תקין.
2023-12-19 12:48:19,411 - clients_logger - ERROR - user send client number to ass debt that cannot be converted to int
Traceback (most recent call last):
  File "c:\Users\User\OneDrive\שולחן העבודה\My assistant project\my_assistant\clients.py", line 357, in debt_amount_to_add
    client_number_to_add_debt = int(update.message.text) - 1
                                ^^^^^^^^^^^^^^^^^^^^^^^^
ValueError: invalid literal for int() with base 10: '46h'
2023-12-19 12:48:23,593 - clients_logger - ERROR - user send number that is bigger than the clients list length
Traceback (most recent call last):
  File "c:\Users\User\OneDrive\שולחן העבודה\My assistant project\my_assistant\clients.py", line 360, in debt_amount_to_add
    raise IndexOfClientIsTooBig()
exceptions.IndexOfClientIsTooBig: הקלדת מספר גדול מידיי שלא נמצא ברשימת הלקוחות, אנא הקלד מספר תקין.
2023-12-19 12:48:30,502 - clients_logger - ERROR - user send client number to ass debt that cannot be converted to int
Traceback (most recent call last):
  File "c:\Users\User\OneDrive\שולחן העבודה\My assistant project\my_assistant\clients.py", line 357, in debt_amount_to_add
    client_number_to_add_debt = int(update.message.text) - 1
                                ^^^^^^^^^^^^^^^^^^^^^^^^
ValueError: invalid literal for int() with base 10: '5h'
2023-12-19 12:52:43,124 - main_logger - INFO - Bot started! Connecting to DB...
2023-12-19 12:52:44,819 - main_logger - INFO - Connected to DB
2023-12-19 12:52:55,834 - clients_logger - ERROR - user send client number to ass debt that cannot be converted to int
Traceback (most recent call last):
  File "c:\Users\User\OneDrive\שולחן העבודה\My assistant project\my_assistant\clients.py", line 357, in debt_amount_to_add
    client_number_to_add_debt = int(update.message.text) - 1
                                ^^^^^^^^^^^^^^^^^^^^^^^^
ValueError: invalid literal for int() with base 10: '16g'
2023-12-19 12:52:58,259 - clients_logger - ERROR - user send number that is bigger than the clients list length
Traceback (most recent call last):
  File "c:\Users\User\OneDrive\שולחן העבודה\My assistant project\my_assistant\clients.py", line 360, in debt_amount_to_add
    raise IndexOfClientIsTooBig()
exceptions.IndexOfClientIsTooBig: הקלדת מספר גדול מידיי שלא נמצא ברשימת הלקוחות, אנא הקלד מספר תקין.
2023-12-19 12:53:15,156 - clients_logger - ERROR - user send client number to ass debt that cannot be converted to int
Traceback (most recent call last):
  File "c:\Users\User\OneDrive\שולחן העבודה\My assistant project\my_assistant\clients.py", line 386, in add_debt
    debt = int(update.message.text)
           ^^^^^^^^^^^^^^^^^^^^^^^^
ValueError: invalid literal for int() with base 10: 'gt6'
2023-12-19 13:10:46,476 - main_logger - INFO - Bot started! Connecting to DB...
2023-12-19 13:10:48,657 - main_logger - INFO - Connected to DB
2023-12-19 13:11:00,226 - clients_logger - ERROR - user send client number to ass debt that cannot be converted to int
Traceback (most recent call last):
  File "c:\Users\User\OneDrive\שולחן העבודה\My assistant project\my_assistant\clients.py", line 609, in send_link
    client_number = int(update.message.text) - 1
                    ^^^^^^^^^^^^^^^^^^^^^^^^
ValueError: invalid literal for int() with base 10: 'g56'
2023-12-19 13:12:19,100 - main_logger - INFO - Bot started! Connecting to DB...
2023-12-19 13:12:21,203 - main_logger - INFO - Connected to DB
2023-12-19 13:12:29,118 - clients_logger - ERROR - user send client number to ass debt that cannot be converted to int
Traceback (most recent call last):
  File "c:\Users\User\OneDrive\שולחן העבודה\My assistant project\my_assistant\clients.py", line 609, in send_link
    client_number = int(update.message.text) - 1
                    ^^^^^^^^^^^^^^^^^^^^^^^^
ValueError: invalid literal for int() with base 10: 'f55'
2023-12-19 13:13:30,017 - clients_logger - ERROR - user send client number to ass debt that cannot be converted to int
Traceback (most recent call last):
  File "c:\Users\User\OneDrive\שולחן העבודה\My assistant project\my_assistant\clients.py", line 609, in send_link
    client_number = int(update.message.text) - 1
                    ^^^^^^^^^^^^^^^^^^^^^^^^
ValueError: invalid literal for int() with base 10: 'g6'
2023-12-19 13:13:33,992 - clients_logger - ERROR - user send number that is bigger than the clients list length
Traceback (most recent call last):
  File "c:\Users\User\OneDrive\שולחן העבודה\My assistant project\my_assistant\clients.py", line 614, in send_link
    raise IndexOfClientIsTooBig()
exceptions.IndexOfClientIsTooBig: הקלדת מספר גדול מידיי שלא נמצא ברשימת הלקוחות, אנא הקלד מספר תקין.
2023-12-19 13:13:40,107 - clients_logger - ERROR - user send number that is bigger than the clients list length
Traceback (most recent call last):
  File "c:\Users\User\OneDrive\שולחן העבודה\My assistant project\my_assistant\clients.py", line 614, in send_link
    raise IndexOfClientIsTooBig()
exceptions.IndexOfClientIsTooBig: הקלדת מספר גדול מידיי שלא נמצא ברשימת הלקוחות, אנא הקלד מספר תקין.
2023-12-19 13:13:43,355 - clients_logger - ERROR - user send client number to ass debt that cannot be converted to int
Traceback (most recent call last):
  File "c:\Users\User\OneDrive\שולחן העבודה\My assistant project\my_assistant\clients.py", line 609, in send_link
    client_number = int(update.message.text) - 1
                    ^^^^^^^^^^^^^^^^^^^^^^^^
ValueError: invalid literal for int() with base 10: '14g'
2023-12-19 13:14:01,325 - main_logger - INFO - Bot started! Connecting to DB...
2023-12-19 13:14:03,307 - main_logger - INFO - Connected to DB
2023-12-19 13:24:53,628 - main_logger - INFO - Bot started! Connecting to DB...
2023-12-19 13:24:56,040 - main_logger - INFO - Connected to DB
2023-12-19 13:25:02,719 - clients_logger - ERROR - user send client number to ass debt that cannot be converted to int
Traceback (most recent call last):
  File "c:\Users\User\OneDrive\שולחן העבודה\My assistant project\my_assistant\clients.py", line 456, in ask_amount_to_delete
    client_number = int(update.message.text) - 1
                    ^^^^^^^^^^^^^^^^^^^^^^^^
ValueError: invalid literal for int() with base 10: 'g6'
2023-12-19 13:25:07,422 - clients_logger - ERROR - user send number that is bigger than the clients list length
Traceback (most recent call last):
  File "c:\Users\User\OneDrive\שולחן העבודה\My assistant project\my_assistant\clients.py", line 466, in ask_amount_to_delete
    raise IndexOfClientIsTooBig()
exceptions.IndexOfClientIsTooBig: הקלדת מספר גדול מידיי שלא נמצא ברשימת הלקוחות, אנא הקלד מספר תקין.
2023-12-19 13:25:17,749 - clients_logger - ERROR - the user send something that cannot be converted to int
Traceback (most recent call last):
  File "c:\Users\User\OneDrive\שולחן העבודה\My assistant project\my_assistant\clients.py", line 560, in delete_part_debt
    debt_to_delete = int(update.message.text)
                     ^^^^^^^^^^^^^^^^^^^^^^^^
ValueError: invalid literal for int() with base 10: 'fr5'
2023-12-19 13:25:23,425 - clients_logger - ERROR - user send number that is bigger than the clients list length
Traceback (most recent call last):
  File "c:\Users\User\OneDrive\שולחן העבודה\My assistant project\my_assistant\clients.py", line 466, in ask_amount_to_delete
    raise IndexOfClientIsTooBig()
exceptions.IndexOfClientIsTooBig: הקלדת מספר גדול מידיי שלא נמצא ברשימת הלקוחות, אנא הקלד מספר תקין.
2023-12-19 13:37:09,973 - main_logger - INFO - Bot started! Connecting to DB...
2023-12-19 13:37:11,685 - main_logger - INFO - Connected to DB
2023-12-19 13:37:29,467 - clients_logger - ERROR - user send client number to ass debt that cannot be converted to int
Traceback (most recent call last):
  File "c:\Users\User\OneDrive\שולחן העבודה\My assistant project\my_assistant\clients.py", line 456, in ask_amount_to_delete
    client_number = int(update.message.text) - 1
                    ^^^^^^^^^^^^^^^^^^^^^^^^
ValueError: invalid literal for int() with base 10: 'כר5'
2023-12-19 13:37:40,846 - clients_logger - ERROR - user send number that is bigger than the clients list length
Traceback (most recent call last):
  File "c:\Users\User\OneDrive\שולחן העבודה\My assistant project\my_assistant\clients.py", line 466, in ask_amount_to_delete
    raise IndexOfClientIsTooBig()
exceptions.IndexOfClientIsTooBig: הקלדת מספר גדול מידיי שלא נמצא ברשימת הלקוחות, אנא הקלד מספר תקין.
2023-12-19 13:38:06,672 - clients_logger - ERROR - the user send something that cannot be converted to int
Traceback (most recent call last):
  File "c:\Users\User\OneDrive\שולחן העבודה\My assistant project\my_assistant\clients.py", line 560, in delete_part_debt
    debt_to_delete = int(update.message.text)
                     ^^^^^^^^^^^^^^^^^^^^^^^^
ValueError: invalid literal for int() with base 10: 'ערא5'
