2023-12-17 13:03:10,488 - main_logger - INFO - Bot started! Connecting to DB...
2023-12-17 13:03:12,452 - main_logger - INFO - Connected to DB
2023-12-17 13:06:59,754 - main_logger - INFO - Bot started! Connecting to DB...
2023-12-17 13:07:02,032 - main_logger - INFO - Connected to DB
2023-12-17 13:14:24,249 - main_logger - INFO - Bot started! Connecting to DB...
2023-12-17 13:14:26,134 - main_logger - INFO - Connected to DB
2023-12-17 13:25:21,119 - main_logger - INFO - Bot started! Connecting to DB...
2023-12-17 13:25:22,747 - main_logger - INFO - Connected to DB
2023-12-17 13:32:18,498 - clients_logger - DEBUG - {'user_id': 222151854, 'username': 'גוון ויינברגר', 'full_name': 'בדיקה1', 'address': 'בדיקה'}
2023-12-17 13:37:14,053 - main_logger - INFO - Bot started! Connecting to DB...
2023-12-17 13:37:15,971 - main_logger - INFO - Connected to DB
2023-12-17 13:37:58,371 - clients_logger - DEBUG - {'user_id': 222151854, 'username': 'גוון ויינברגר', 'full_name': 'בדיקה1', 'address': 'בדיקה'}
2023-12-17 13:38:10,092 - db_connection_logger - INFO - user tried to add client that is already in the list
2023-12-17 13:38:10,093 - db_connection_logger - ERROR - unable to add client to data base
2023-12-17 13:41:04,789 - main_logger - INFO - Bot started! Connecting to DB...
2023-12-17 13:41:06,180 - main_logger - INFO - Connected to DB
2023-12-17 13:42:32,704 - clients_logger - DEBUG - {'user_id': 222151854, 'username': 'גוון ויינברגר', 'full_name': 'בדיקה3', 'address': 'בדיקה'}
2023-12-17 13:42:42,840 - clients_logger - DEBUG - {'user_id': 222151854, 'username': 'גוון ויינברגר', 'full_name': 'תבדיקה4', 'address': 'בדיקה'}
2023-12-17 13:44:08,811 - main_logger - INFO - Bot started! Connecting to DB...
2023-12-17 13:44:10,692 - main_logger - INFO - Connected to DB
2023-12-17 14:01:18,437 - main_logger - INFO - Bot started! Connecting to DB...
2023-12-17 14:01:20,446 - main_logger - INFO - Connected to DB
2023-12-17 14:01:37,551 - clients_logger - DEBUG - {'user_id': 222151854, 'username': 'גוון ויינברגר', 'full_name': 'בדיקה1', 'address': 'בדיקה'}
2023-12-17 14:01:50,762 - clients_logger - DEBUG - {'user_id': 222151854, 'username': 'גוון ויינברגר', 'full_name': 'בדיקה2', 'address': 'בדיקה'}
2023-12-17 14:02:16,679 - clients_logger - DEBUG - {'user_id': 222151854, 'username': 'גוון ויינברגר', 'full_name': 'תבדיקה3', 'address': 'בדיקה'}
2023-12-17 14:04:17,045 - main_logger - INFO - Bot started! Connecting to DB...
2023-12-17 14:04:19,444 - main_logger - INFO - Connected to DB
2023-12-17 14:09:52,831 - main_logger - INFO - Bot started! Connecting to DB...
2023-12-17 14:09:55,119 - main_logger - INFO - Connected to DB
2023-12-17 14:13:08,259 - main_logger - INFO - Bot started! Connecting to DB...
2023-12-17 14:13:10,285 - main_logger - INFO - Connected to DB
2023-12-17 14:15:45,733 - main_logger - INFO - Bot started! Connecting to DB...
2023-12-17 14:15:47,787 - main_logger - INFO - Connected to DB
2023-12-17 14:16:21,994 - clients_logger - DEBUG - {'user_id': 222151854, 'username': 'גוון ויינברגר', 'full_name': 'גוון', 'address': 'בדיקה1'}
2023-12-17 14:16:51,077 - clients_logger - DEBUG - {'user_id': 222151854, 'username': 'גוון ויינברגר', 'full_name': 'בדיקה1', 'address': 'בדיקה2'}
2023-12-17 14:21:44,854 - main_logger - INFO - Bot started! Connecting to DB...
2023-12-17 14:21:46,529 - main_logger - INFO - Connected to DB
2023-12-17 14:21:58,130 - clients_logger - DEBUG - {'user_id': 222151854, 'username': 'גוון ויינברגר', 'full_name': 'גוון', 'address': 'ויינברגר'}
2023-12-17 14:22:49,775 - clients_logger - ERROR - can't show buttons with names of client to delete
Traceback (most recent call last):
  File "c:\Users\User\OneDrive\שולחן העבודה\My assistant project\my_assistant\clients.py", line 258, in next_page
    await update.callback_query.message.reply_text(reply_markup=reply_markup, parse_mode='Markdown')
          ^^^^^^^^^^^^^^^^^^^^^^^^^^^^^^^^^^^^^^^^^^^^^^^^^^^^^^^^^^^^^^^^^^^^^^^^^^^^^^^^^^^^^^^^^^
TypeError: Message.reply_text() missing 1 required positional argument: 'text'
2023-12-17 14:24:01,160 - main_logger - INFO - Bot started! Connecting to DB...
2023-12-17 14:24:02,988 - main_logger - INFO - Connected to DB
2023-12-17 14:24:10,550 - clients_logger - ERROR - can't show buttons with names of client to delete
Traceback (most recent call last):
  File "c:\Users\User\OneDrive\שולחן העבודה\My assistant project\my_assistant\clients.py", line 258, in next_page
    await update.callback_query.message.reply_text("", reply_markup=reply_markup, parse_mode='Markdown')
  File "C:\Users\User\OneDrive\שולחן העבודה\My assistant project\venv\Lib\site-packages\telegram\_message.py", line 1094, in reply_text
    return await self.get_bot().send_message(
           ^^^^^^^^^^^^^^^^^^^^^^^^^^^^^^^^^^
  File "C:\Users\User\OneDrive\שולחן העבודה\My assistant project\venv\Lib\site-packages\telegram\ext\_extbot.py", line 2624, in send_message
    return await super().send_message(
           ^^^^^^^^^^^^^^^^^^^^^^^^^^^
  File "C:\Users\User\OneDrive\שולחן העבודה\My assistant project\venv\Lib\site-packages\telegram\_bot.py", line 525, in decorator
    result = await func(self, *args, **kwargs)  # skipcq: PYL-E1102
             ^^^^^^^^^^^^^^^^^^^^^^^^^^^^^^^^^
  File "C:\Users\User\OneDrive\שולחן העבודה\My assistant project\venv\Lib\site-packages\telegram\_bot.py", line 846, in send_message
    return await self._send_message(
           ^^^^^^^^^^^^^^^^^^^^^^^^^
  File "C:\Users\User\OneDrive\שולחן העבודה\My assistant project\venv\Lib\site-packages\telegram\ext\_extbot.py", line 522, in _send_message
    result = await super()._send_message(
             ^^^^^^^^^^^^^^^^^^^^^^^^^^^^
  File "C:\Users\User\OneDrive\שולחן העבודה\My assistant project\venv\Lib\site-packages\telegram\_bot.py", line 703, in _send_message
    result = await self._post(
             ^^^^^^^^^^^^^^^^^
  File "C:\Users\User\OneDrive\שולחן העבודה\My assistant project\venv\Lib\site-packages\telegram\_bot.py", line 613, in _post
    return await self._do_post(
           ^^^^^^^^^^^^^^^^^^^^
  File "C:\Users\User\OneDrive\שולחן העבודה\My assistant project\venv\Lib\site-packages\telegram\ext\_extbot.py", line 340, in _do_post
    return await super()._do_post(
           ^^^^^^^^^^^^^^^^^^^^^^^
  File "C:\Users\User\OneDrive\שולחן העבודה\My assistant project\venv\Lib\site-packages\telegram\_bot.py", line 641, in _do_post
    return await request.post(
           ^^^^^^^^^^^^^^^^^^^
  File "C:\Users\User\OneDrive\שולחן העבודה\My assistant project\venv\Lib\site-packages\telegram\request\_baserequest.py", line 200, in post
    result = await self._request_wrapper(
             ^^^^^^^^^^^^^^^^^^^^^^^^^^^^
  File "C:\Users\User\OneDrive\שולחן העבודה\My assistant project\venv\Lib\site-packages\telegram\request\_baserequest.py", line 379, in _request_wrapper
    raise BadRequest(message)
telegram.error.BadRequest: Message text is empty
2023-12-17 14:24:53,645 - main_logger - INFO - Bot started! Connecting to DB...
2023-12-17 14:24:55,216 - main_logger - INFO - Connected to DB
2023-12-17 14:26:33,536 - clients_logger - DEBUG - {'user_id': 222151854, 'username': 'גוון ויינברגר', 'full_name': 'רומי מזרחי', 'address': 'זום'}
2023-12-17 14:29:22,414 - main_logger - INFO - Bot started! Connecting to DB...
2023-12-17 14:29:24,273 - main_logger - INFO - Connected to DB
2023-12-17 14:36:02,061 - main_logger - INFO - Bot started! Connecting to DB...
2023-12-17 14:36:03,818 - main_logger - INFO - Connected to DB
2023-12-17 14:41:03,549 - main_logger - INFO - Bot started! Connecting to DB...
2023-12-17 14:41:05,174 - main_logger - INFO - Connected to DB
2023-12-17 14:41:33,681 - clients_logger - ERROR - The parameter `inline_keyboard` should be a sequence of sequences of InlineKeyboardButtons
Traceback (most recent call last):
  File "c:\Users\User\OneDrive\שולחן העבודה\My assistant project\my_assistant\clients.py", line 129, in show_clients_callback
    reply_markup = InlineKeyboardMarkup(keyboard)
                   ^^^^^^^^^^^^^^^^^^^^^^^^^^^^^^
  File "C:\Users\User\OneDrive\שולחן העבודה\My assistant project\venv\Lib\site-packages\telegram\_inline\inlinekeyboardmarkup.py", line 79, in __init__
    raise ValueError(
ValueError: The parameter `inline_keyboard` should be a sequence of sequences of InlineKeyboardButtons
2023-12-17 14:42:14,116 - clients_logger - ERROR - The parameter `inline_keyboard` should be a sequence of sequences of InlineKeyboardButtons
Traceback (most recent call last):
  File "c:\Users\User\OneDrive\שולחן העבודה\My assistant project\my_assistant\clients.py", line 129, in show_clients_callback
    reply_markup = InlineKeyboardMarkup(keyboard)
                   ^^^^^^^^^^^^^^^^^^^^^^^^^^^^^^
  File "C:\Users\User\OneDrive\שולחן העבודה\My assistant project\venv\Lib\site-packages\telegram\_inline\inlinekeyboardmarkup.py", line 79, in __init__
    raise ValueError(
ValueError: The parameter `inline_keyboard` should be a sequence of sequences of InlineKeyboardButtons
2023-12-17 14:43:31,693 - main_logger - INFO - Bot started! Connecting to DB...
2023-12-17 14:43:33,566 - main_logger - INFO - Connected to DB
2023-12-18 10:35:44,035 - main_logger - INFO - Bot started! Connecting to DB...
2023-12-18 10:35:45,873 - main_logger - INFO - Connected to DB
2023-12-18 10:58:02,952 - main_logger - INFO - Bot started! Connecting to DB...
2023-12-18 10:58:04,880 - main_logger - INFO - Connected to DB
2023-12-18 10:59:23,953 - main_logger - INFO - Bot started! Connecting to DB...
2023-12-18 10:59:25,727 - main_logger - INFO - Connected to DB
2023-12-18 11:30:34,999 - main_logger - INFO - Bot started! Connecting to DB...
2023-12-18 11:30:36,729 - main_logger - INFO - Connected to DB
2023-12-18 11:30:50,622 - clients_logger - DEBUG - [{'id': 26, 'full_name': 'אגם כהן', 'address': 'זום', 'debt': 0, 'create_time': datetime.datetime(2023, 12, 14, 21, 57, 13), 'user_id': '222151854', 'username': 'גוון ויינברגר'}, {'id': 49, 'full_name': 'אלכסנדרה אהרון', 'address': 'זום', 'debt': 120, 'create_time': datetime.datetime(2023, 12, 17, 10, 26, 5), 'user_id': '222151854', 'username': 'גוון ויינברגר'}, {'id': 30, 'full_name': 'אסף בובק', 'address': 'זום', 'debt': 100, 'create_time': datetime.datetime(2023, 12, 16, 19, 31, 58), 'user_id': '222151854', 'username': 'גוון ויינברגר'}, {'id': 31, 'full_name': 'דביר סולמי', 'address': 'זום', 'debt': 0, 'create_time': datetime.datetime(2023, 12, 16, 19, 32, 56), 'user_id': '222151854', 'username': 'גוון ויינברגר'}, {'id': 37, 'full_name': 'דרור מזרחי', 'address': 'זום', 'debt': 0, 'create_time': datetime.datetime(2023, 12, 16, 19, 38, 13), 'user_id': '222151854', 'username': 'גוון ויינברגר'}, {'id': 36, 'full_name': 'נדב כהן', 'address': 'הדקל 22 לפיד', 'debt': 0, 'create_time': datetime.datetime(2023, 12, 16, 19, 37, 34), 'user_id': '222151854', 'username': 'גוון ויינברגר'}, {'id': 33, 'full_name': 'נועם אפשטיין', 'address': 'הזית 74 לפיד', 'debt': 0, 'create_time': datetime.datetime(2023, 12, 16, 19, 35, 27), 'user_id': '222151854', 'username': 'גוון ויינברגר'}, {'id': 29, 'full_name': 'עדי לוי', 'address': 'שבטי ישראל 17 מודיעין', 'debt': 0, 'create_time': datetime.datetime(2023, 12, 16, 19, 31, 44), 'user_id': '222151854', 'username': 'גוון ויינברגר'}, {'id': 24, 'full_name': 'עדי עזרא', 'address': 'זום', 'debt': 0, 'create_time': datetime.datetime(2023, 12, 14, 16, 52, 45), 'user_id': '222151854', 'username': 'גוון ויינברגר'}, {'id': 32, 'full_name': 'עומרי נוף', 'address': 'זום', 'debt': 0, 'create_time': datetime.datetime(2023, 12, 16, 19, 34, 48), 'user_id': '222151854', 'username': 'גוון ויינברגר'}, {'id': 38, 'full_name': 'עופרי עזרא', 'address': 'זום', 'debt': 0, 'create_time': datetime.datetime(2023, 12, 17, 9, 53, 24), 'user_id': '222151854', 'username': 'גוון ויינברגר'}, {'id': 78, 'full_name': 'רומי מזרחי', 'address': 'זום', 'debt': 0, 'create_time': datetime.datetime(2023, 12, 17, 12, 26, 7), 'user_id': '222151854', 'username': 'גוון ויינברגר'}, {'id': 34, 'full_name': 'שירה זנטי', 'address': 'גורדון 23 נווה שאנן חיפה', 'debt': 0, 'create_time': datetime.datetime(2023, 12, 16, 19, 36, 30), 'user_id': '222151854', 'username': 'גוון ויינברגר'}]
2023-12-18 11:40:06,818 - main_logger - INFO - Bot started! Connecting to DB...
2023-12-18 11:40:08,182 - main_logger - INFO - Connected to DB
2023-12-18 11:40:58,008 - main_logger - INFO - Bot started! Connecting to DB...
2023-12-18 11:40:59,238 - main_logger - INFO - Connected to DB
2023-12-18 13:10:17,173 - main_logger - INFO - Bot started! Connecting to DB...
2023-12-18 13:10:19,016 - main_logger - INFO - Connected to DB
2023-12-18 13:10:51,047 - main_logger - INFO - Bot started! Connecting to DB...
2023-12-18 13:10:52,696 - main_logger - INFO - Connected to DB
2023-12-18 13:14:15,856 - main_logger - INFO - Bot started! Connecting to DB...
2023-12-18 13:14:18,050 - main_logger - INFO - Connected to DB
2023-12-18 13:14:38,329 - db_connection_logger - ERROR - unable to add debt to the client in the data base
2023-12-18 13:14:38,340 - clients_logger - ERROR - 1054 (42S22): Unknown column 'client_id' in 'where clause'
Traceback (most recent call last):
  File "C:\Users\User\OneDrive\שולחן העבודה\My assistant project\venv\Lib\site-packages\mysql\connector\connection_cext.py", line 639, in cmd_query
    self._cmysql.query(
_mysql_connector.MySQLInterfaceError: Unknown column 'client_id' in 'where clause'

The above exception was the direct cause of the following exception:

Traceback (most recent call last):
  File "c:\Users\User\OneDrive\שולחן העבודה\My assistant project\my_assistant\clients.py", line 372, in add_debt
    add_debt_to_db(client_id=client_id, user_id=user_id, debt_to_add=debt)
  File "c:\Users\User\OneDrive\שולחן העבודה\My assistant project\my_assistant\db_connection.py", line 118, in add_debt_to_db
    db_cursor.execute(sql_add_debt, (debt_to_add, client_id, user_id))
  File "C:\Users\User\OneDrive\שולחן העבודה\My assistant project\venv\Lib\site-packages\mysql\connector\cursor_cext.py", line 330, in execute
    result = self._cnx.cmd_query(
             ^^^^^^^^^^^^^^^^^^^^
  File "C:\Users\User\OneDrive\שולחן העבודה\My assistant project\venv\Lib\site-packages\mysql\connector\opentelemetry\context_propagation.py", line 77, in wrapper
    return method(cnx, *args, **kwargs)
           ^^^^^^^^^^^^^^^^^^^^^^^^^^^^
  File "C:\Users\User\OneDrive\שולחן העבודה\My assistant project\venv\Lib\site-packages\mysql\connector\connection_cext.py", line 647, in cmd_query
    raise get_mysql_exception(
mysql.connector.errors.ProgrammingError: 1054 (42S22): Unknown column 'client_id' in 'where clause'
2023-12-18 13:19:29,371 - main_logger - INFO - Bot started! Connecting to DB...
2023-12-18 13:19:30,746 - main_logger - INFO - Connected to DB
2023-12-18 13:19:49,998 - clients_logger - DEBUG - 49
2023-12-18 13:19:50,009 - clients_logger - DEBUG - {'id': 49, 'full_name': 'אלכסנדרה אהרון', 'address': 'זום', 'debt': 0, 'create_time': datetime.datetime(2023, 12, 17, 10, 26, 5), 'user_id': '222151854', 'username': 'גוון ויינברגר'}
2023-12-18 13:19:50,161 - db_connection_logger - ERROR - unable to add debt to the client in the data base
2023-12-18 13:19:50,169 - clients_logger - ERROR - 1054 (42S22): Unknown column 'client_id' in 'where clause'
Traceback (most recent call last):
  File "C:\Users\User\OneDrive\שולחן העבודה\My assistant project\venv\Lib\site-packages\mysql\connector\connection_cext.py", line 639, in cmd_query
    self._cmysql.query(
_mysql_connector.MySQLInterfaceError: Unknown column 'client_id' in 'where clause'

The above exception was the direct cause of the following exception:

Traceback (most recent call last):
  File "c:\Users\User\OneDrive\שולחן העבודה\My assistant project\my_assistant\clients.py", line 376, in add_debt
    add_debt_to_db(client_id=client_id, user_id=user_id, debt_to_add=debt)
  File "c:\Users\User\OneDrive\שולחן העבודה\My assistant project\my_assistant\db_connection.py", line 118, in add_debt_to_db
    db_cursor.execute(sql_add_debt, (debt_to_add, client_id, user_id))
  File "C:\Users\User\OneDrive\שולחן העבודה\My assistant project\venv\Lib\site-packages\mysql\connector\cursor_cext.py", line 330, in execute
    result = self._cnx.cmd_query(
             ^^^^^^^^^^^^^^^^^^^^
  File "C:\Users\User\OneDrive\שולחן העבודה\My assistant project\venv\Lib\site-packages\mysql\connector\opentelemetry\context_propagation.py", line 77, in wrapper
    return method(cnx, *args, **kwargs)
           ^^^^^^^^^^^^^^^^^^^^^^^^^^^^
  File "C:\Users\User\OneDrive\שולחן העבודה\My assistant project\venv\Lib\site-packages\mysql\connector\connection_cext.py", line 647, in cmd_query
    raise get_mysql_exception(
mysql.connector.errors.ProgrammingError: 1054 (42S22): Unknown column 'client_id' in 'where clause'
2023-12-18 13:22:15,105 - main_logger - INFO - Bot started! Connecting to DB...
2023-12-18 13:22:16,819 - main_logger - INFO - Connected to DB
2023-12-18 13:22:39,282 - clients_logger - DEBUG - 49
2023-12-18 13:22:39,283 - clients_logger - DEBUG - {'id': 49, 'full_name': 'אלכסנדרה אהרון', 'address': 'זום', 'debt': 0, 'create_time': datetime.datetime(2023, 12, 17, 10, 26, 5), 'user_id': '222151854', 'username': 'גוון ויינברגר'}
2023-12-18 13:23:15,658 - clients_logger - DEBUG - 32
2023-12-18 13:23:15,660 - clients_logger - DEBUG - {'id': 32, 'full_name': 'עומרי נוף', 'address': 'זום', 'debt': 0, 'create_time': datetime.datetime(2023, 12, 16, 19, 34, 48), 'user_id': '222151854', 'username': 'גוון ויינברגר'}
2023-12-18 13:23:28,533 - clients_logger - DEBUG - 49
2023-12-18 13:23:28,535 - clients_logger - DEBUG - {'id': 49, 'full_name': 'אלכסנדרה אהרון', 'address': 'זום', 'debt': 120, 'create_time': datetime.datetime(2023, 12, 17, 10, 26, 5), 'user_id': '222151854', 'username': 'גוון ויינברגר'}
2023-12-18 13:25:02,091 - main_logger - INFO - Bot started! Connecting to DB...
2023-12-18 13:25:03,987 - main_logger - INFO - Connected to DB
2023-12-18 13:27:11,572 - main_logger - INFO - Bot started! Connecting to DB...
2023-12-18 13:27:13,297 - main_logger - INFO - Connected to DB
2023-12-18 14:54:18,586 - main_logger - INFO - Bot started! Connecting to DB...
2023-12-18 14:54:20,456 - main_logger - INFO - Connected to DB
2023-12-18 14:54:44,595 - clients_logger - ERROR - name 'client_name' is not defined
Traceback (most recent call last):
  File "c:\Users\User\OneDrive\שולחן העבודה\My assistant project\my_assistant\clients.py", line 459, in ask_amount_to_delete
    await update.message.reply_text(f'*ללקוח/ה {client_name} יש חוב של {client_debt}.*\n בחר את הפעולה הרצוייה או לחץ /cancel לביטול',
                                                ^^^^^^^^^^^
NameError: name 'client_name' is not defined. Did you mean: 'client_number'?
2023-12-18 14:55:43,942 - main_logger - INFO - Bot started! Connecting to DB...
2023-12-18 14:55:45,636 - main_logger - INFO - Connected to DB
2023-12-18 14:56:01,469 - db_connection_logger - ERROR - unable to delete debt to the client in the data base
2023-12-18 14:56:01,479 - clients_logger - ERROR - name 'debt_to_add' is not defined
Traceback (most recent call last):
  File "c:\Users\User\OneDrive\שולחן העבודה\My assistant project\my_assistant\clients.py", line 488, in delete_all_debt
    delete_debt_from_db(
  File "c:\Users\User\OneDrive\שולחן העבודה\My assistant project\my_assistant\db_connection.py", line 134, in delete_debt_from_db
    db_cursor.execute(sql_delete_debt, (debt_to_add, client_id, user_id))
                                        ^^^^^^^^^^^
NameError: name 'debt_to_add' is not defined
2023-12-18 14:56:38,745 - main_logger - INFO - Bot started! Connecting to DB...
2023-12-18 14:56:40,007 - main_logger - INFO - Connected to DB
2023-12-18 18:16:28,300 - main_logger - INFO - Bot started! Connecting to DB...
2023-12-18 18:16:31,598 - main_logger - INFO - Connected to DB
2023-12-18 18:35:12,612 - main_logger - INFO - Bot started! Connecting to DB...
2023-12-18 18:35:14,330 - main_logger - INFO - Connected to DB
2023-12-18 18:38:50,323 - clients_logger - ERROR - list index out of range
Traceback (most recent call last):
  File "c:\Users\User\OneDrive\שולחן העבודה\My assistant project\my_assistant\clients.py", line 375, in add_debt
    client_id = (clients_list[client_number_to_add_debt])["id"]
                 ~~~~~~~~~~~~^^^^^^^^^^^^^^^^^^^^^^^^^^^
IndexError: list index out of range
2023-12-18 18:42:08,714 - main_logger - INFO - Bot started! Connecting to DB...
2023-12-18 18:42:10,387 - main_logger - INFO - Connected to DB
2023-12-18 19:10:39,554 - main_logger - INFO - Bot started! Connecting to DB...
2023-12-18 19:10:41,147 - main_logger - INFO - Connected to DB
2023-12-18 19:59:03,614 - main_logger - INFO - Bot started! Connecting to DB...
2023-12-18 19:59:05,236 - main_logger - INFO - Connected to DB
2023-12-19 09:27:56,173 - main_logger - INFO - Bot started! Connecting to DB...
2023-12-19 09:27:58,263 - main_logger - INFO - Connected to DB
2023-12-19 09:39:09,338 - main_logger - INFO - Bot started! Connecting to DB...
2023-12-19 09:39:11,237 - main_logger - INFO - Connected to DB
2023-12-19 10:01:21,439 - main_logger - INFO - Bot started! Connecting to DB...
2023-12-19 10:01:23,583 - main_logger - INFO - Connected to DB
2023-12-19 10:02:41,181 - db_connection_logger - INFO - the user tried to add client that is already exists
2023-12-19 10:03:42,421 - main_logger - INFO - Bot started! Connecting to DB...
2023-12-19 10:03:44,258 - main_logger - INFO - Connected to DB
2023-12-19 10:10:39,820 - main_logger - INFO - Bot started! Connecting to DB...
2023-12-19 10:10:41,570 - main_logger - INFO - Connected to DB
2023-12-19 10:10:54,942 - clients_logger - DEBUG - keyError happens: 'address'
2023-12-19 10:17:11,078 - main_logger - INFO - Bot started! Connecting to DB...
2023-12-19 10:17:12,791 - main_logger - INFO - Connected to DB
2023-12-19 10:17:29,382 - db_connection_logger - INFO - clients details not full!
2023-12-19 10:21:35,036 - main_logger - INFO - Bot started! Connecting to DB...
2023-12-19 10:21:36,976 - main_logger - INFO - Connected to DB
2023-12-19 10:21:50,156 - clients_logger - DEBUG - key error:'לא כל פרטי הלקוח מלאים, נא השלם את הפרטים החסרים.'
2023-12-19 10:26:05,996 - main_logger - INFO - Bot started! Connecting to DB...
2023-12-19 10:26:07,791 - main_logger - INFO - Connected to DB
2023-12-19 10:26:25,444 - db_connection_logger - INFO - clients details are not full.
2023-12-19 10:27:27,088 - main_logger - INFO - Bot started! Connecting to DB...
2023-12-19 10:27:28,876 - main_logger - INFO - Connected to DB
2023-12-19 10:31:19,358 - main_logger - INFO - Bot started! Connecting to DB...
2023-12-19 10:31:21,345 - main_logger - INFO - Connected to DB
2023-12-19 10:31:30,622 - db_connection_logger - INFO - clients details are not full.
2023-12-19 10:31:30,624 - clients_logger - DEBUG - 'לא כל פרטי הלקוח מלאים, נא השלם את הפרטים החסרים.'
2023-12-19 10:32:34,363 - main_logger - INFO - Bot started! Connecting to DB...
2023-12-19 10:32:36,087 - main_logger - INFO - Connected to DB
2023-12-19 10:32:54,632 - db_connection_logger - INFO - clients details are not full.
2023-12-19 10:32:54,633 - clients_logger - DEBUG - 'לא כל פרטי הלקוח מלאים, נא השלם את הפרטים החסרים.'
2023-12-19 10:33:36,398 - main_logger - INFO - Bot started! Connecting to DB...
2023-12-19 10:33:38,054 - main_logger - INFO - Connected to DB
2023-12-19 10:33:44,896 - db_connection_logger - INFO - clients details are not full.
2023-12-19 10:35:28,438 - main_logger - INFO - Bot started! Connecting to DB...
2023-12-19 10:35:30,267 - main_logger - INFO - Connected to DB
2023-12-19 10:35:44,123 - db_connection_logger - INFO - clients details are not full.
2023-12-19 10:36:17,227 - main_logger - INFO - Bot started! Connecting to DB...
2023-12-19 10:36:18,758 - main_logger - INFO - Connected to DB
2023-12-19 10:36:24,050 - db_connection_logger - INFO - clients details are not full.
2023-12-19 10:36:37,411 - main_logger - INFO - Bot started! Connecting to DB...
2023-12-19 10:36:39,097 - main_logger - INFO - Connected to DB
2023-12-19 10:36:42,983 - db_connection_logger - INFO - clients details are not full.
2023-12-19 10:36:42,986 - clients_logger - INFO - {}
2023-12-19 10:37:19,889 - main_logger - INFO - Bot started! Connecting to DB...
2023-12-19 10:37:21,440 - main_logger - INFO - Connected to DB
2023-12-19 10:37:28,694 - db_connection_logger - INFO - clients details are not full.
2023-12-19 10:40:24,794 - db_connection_logger - INFO - clients details are not full.
2023-12-19 10:40:56,416 - main_logger - INFO - Bot started! Connecting to DB...
2023-12-19 10:40:57,968 - main_logger - INFO - Connected to DB
2023-12-19 10:41:08,413 - db_connection_logger - INFO - the user tried to add client that is already exists
2023-12-19 11:08:59,069 - main_logger - INFO - Bot started! Connecting to DB...
2023-12-19 11:09:01,547 - main_logger - INFO - Connected to DB
2023-12-19 11:10:58,444 - main_logger - INFO - Bot started! Connecting to DB...
2023-12-19 11:11:00,541 - main_logger - INFO - Connected to DB
2023-12-19 11:44:39,098 - main_logger - INFO - Bot started! Connecting to DB...
2023-12-19 11:44:40,631 - main_logger - INFO - Connected to DB
2023-12-19 11:49:19,321 - main_logger - INFO - Bot started! Connecting to DB...
2023-12-19 11:49:21,216 - main_logger - INFO - Connected to DB
2023-12-19 11:52:07,582 - main_logger - INFO - Bot started! Connecting to DB...
2023-12-19 11:52:09,545 - main_logger - INFO - Connected to DB
2023-12-19 12:06:57,142 - main_logger - INFO - Bot started! Connecting to DB...
2023-12-19 12:06:59,021 - main_logger - INFO - Connected to DB
2023-12-19 12:08:29,015 - clients_logger - ERROR - the user send something that cannot be converted to int
Traceback (most recent call last):
  File "c:\Users\User\OneDrive\שולחן העבודה\My assistant project\my_assistant\clients.py", line 515, in delete_part_debt
    debt_to_delete = int(update.message.text)
                     ^^^^^^^^^^^^^^^^^^^^^^^^
ValueError: invalid literal for int() with base 10: '6כק'
2023-12-19 12:13:31,005 - main_logger - INFO - Bot started! Connecting to DB...
2023-12-19 12:13:32,901 - main_logger - INFO - Connected to DB
2023-12-19 12:13:50,759 - clients_logger - ERROR - the user send something that cannot be converted to int
Traceback (most recent call last):
  File "c:\Users\User\OneDrive\שולחן העבודה\My assistant project\my_assistant\clients.py", line 515, in delete_part_debt
    debt_to_delete = int(update.message.text)
                     ^^^^^^^^^^^^^^^^^^^^^^^^
ValueError: invalid literal for int() with base 10: '15חי'
2023-12-19 12:19:50,262 - main_logger - INFO - Bot started! Connecting to DB...
2023-12-19 12:19:52,158 - main_logger - INFO - Connected to DB
2023-12-19 12:20:06,952 - clients_logger - ERROR - user send client number to ass debt that cannot be converted to int
Traceback (most recent call last):
  File "c:\Users\User\OneDrive\שולחן העבודה\My assistant project\my_assistant\clients.py", line 351, in debt_amount_to_add
    client_number_to_add_debt = int(update.message.text) - 1
                                ^^^^^^^^^^^^^^^^^^^^^^^^
ValueError: invalid literal for int() with base 10: 'g6'
2023-12-19 12:24:55,231 - main_logger - INFO - Bot started! Connecting to DB...
2023-12-19 12:24:57,002 - main_logger - INFO - Connected to DB
2023-12-19 12:25:07,714 - clients_logger - ERROR - user send client number to ass debt that cannot be converted to int
Traceback (most recent call last):
  File "c:\Users\User\OneDrive\שולחן העבודה\My assistant project\my_assistant\clients.py", line 351, in debt_amount_to_add
    client_number_to_add_debt = int(update.message.text) - 1
                                ^^^^^^^^^^^^^^^^^^^^^^^^
ValueError: invalid literal for int() with base 10: 'g6'
2023-12-19 12:25:42,901 - clients_logger - ERROR - list index out of range
Traceback (most recent call last):
  File "c:\Users\User\OneDrive\שולחן העבודה\My assistant project\my_assistant\clients.py", line 373, in add_debt
    client_id = (clients_list[client_number_to_add_debt])["id"]
                 ~~~~~~~~~~~~^^^^^^^^^^^^^^^^^^^^^^^^^^^
IndexError: list index out of range
2023-12-19 12:36:16,140 - main_logger - INFO - Bot started! Connecting to DB...
2023-12-19 12:36:17,970 - main_logger - INFO - Connected to DB
2023-12-19 12:38:14,832 - main_logger - INFO - Bot started! Connecting to DB...
2023-12-19 12:38:16,655 - main_logger - INFO - Connected to DB
2023-12-19 12:43:58,006 - main_logger - INFO - Bot started! Connecting to DB...
2023-12-19 12:43:59,901 - main_logger - INFO - Connected to DB
2023-12-19 12:45:17,130 - main_logger - INFO - Bot started! Connecting to DB...
2023-12-19 12:45:19,342 - main_logger - INFO - Connected to DB
2023-12-19 12:47:13,243 - clients_logger - ERROR - user send number that is bigger than the clients list length
Traceback (most recent call last):
  File "c:\Users\User\OneDrive\שולחן העבודה\My assistant project\my_assistant\clients.py", line 360, in debt_amount_to_add
    raise IndexOfClientIsTooBig()
exceptions.IndexOfClientIsTooBig: הקלדת מספר גדול מידיי שלא נמצא ברשימת הלקוחות, אנא הקלד מספר תקין.
2023-12-19 12:48:19,411 - clients_logger - ERROR - user send client number to ass debt that cannot be converted to int
Traceback (most recent call last):
  File "c:\Users\User\OneDrive\שולחן העבודה\My assistant project\my_assistant\clients.py", line 357, in debt_amount_to_add
    client_number_to_add_debt = int(update.message.text) - 1
                                ^^^^^^^^^^^^^^^^^^^^^^^^
ValueError: invalid literal for int() with base 10: '46h'
2023-12-19 12:48:23,593 - clients_logger - ERROR - user send number that is bigger than the clients list length
Traceback (most recent call last):
  File "c:\Users\User\OneDrive\שולחן העבודה\My assistant project\my_assistant\clients.py", line 360, in debt_amount_to_add
    raise IndexOfClientIsTooBig()
exceptions.IndexOfClientIsTooBig: הקלדת מספר גדול מידיי שלא נמצא ברשימת הלקוחות, אנא הקלד מספר תקין.
2023-12-19 12:48:30,502 - clients_logger - ERROR - user send client number to ass debt that cannot be converted to int
Traceback (most recent call last):
  File "c:\Users\User\OneDrive\שולחן העבודה\My assistant project\my_assistant\clients.py", line 357, in debt_amount_to_add
    client_number_to_add_debt = int(update.message.text) - 1
                                ^^^^^^^^^^^^^^^^^^^^^^^^
ValueError: invalid literal for int() with base 10: '5h'
2023-12-19 12:52:43,124 - main_logger - INFO - Bot started! Connecting to DB...
2023-12-19 12:52:44,819 - main_logger - INFO - Connected to DB
2023-12-19 12:52:55,834 - clients_logger - ERROR - user send client number to ass debt that cannot be converted to int
Traceback (most recent call last):
  File "c:\Users\User\OneDrive\שולחן העבודה\My assistant project\my_assistant\clients.py", line 357, in debt_amount_to_add
    client_number_to_add_debt = int(update.message.text) - 1
                                ^^^^^^^^^^^^^^^^^^^^^^^^
ValueError: invalid literal for int() with base 10: '16g'
2023-12-19 12:52:58,259 - clients_logger - ERROR - user send number that is bigger than the clients list length
Traceback (most recent call last):
  File "c:\Users\User\OneDrive\שולחן העבודה\My assistant project\my_assistant\clients.py", line 360, in debt_amount_to_add
    raise IndexOfClientIsTooBig()
exceptions.IndexOfClientIsTooBig: הקלדת מספר גדול מידיי שלא נמצא ברשימת הלקוחות, אנא הקלד מספר תקין.
2023-12-19 12:53:15,156 - clients_logger - ERROR - user send client number to ass debt that cannot be converted to int
Traceback (most recent call last):
  File "c:\Users\User\OneDrive\שולחן העבודה\My assistant project\my_assistant\clients.py", line 386, in add_debt
    debt = int(update.message.text)
           ^^^^^^^^^^^^^^^^^^^^^^^^
ValueError: invalid literal for int() with base 10: 'gt6'
2023-12-19 13:10:46,476 - main_logger - INFO - Bot started! Connecting to DB...
2023-12-19 13:10:48,657 - main_logger - INFO - Connected to DB
2023-12-19 13:11:00,226 - clients_logger - ERROR - user send client number to ass debt that cannot be converted to int
Traceback (most recent call last):
  File "c:\Users\User\OneDrive\שולחן העבודה\My assistant project\my_assistant\clients.py", line 609, in send_link
    client_number = int(update.message.text) - 1
                    ^^^^^^^^^^^^^^^^^^^^^^^^
ValueError: invalid literal for int() with base 10: 'g56'
2023-12-19 13:12:19,100 - main_logger - INFO - Bot started! Connecting to DB...
2023-12-19 13:12:21,203 - main_logger - INFO - Connected to DB
2023-12-19 13:12:29,118 - clients_logger - ERROR - user send client number to ass debt that cannot be converted to int
Traceback (most recent call last):
  File "c:\Users\User\OneDrive\שולחן העבודה\My assistant project\my_assistant\clients.py", line 609, in send_link
    client_number = int(update.message.text) - 1
                    ^^^^^^^^^^^^^^^^^^^^^^^^
ValueError: invalid literal for int() with base 10: 'f55'
2023-12-19 13:13:30,017 - clients_logger - ERROR - user send client number to ass debt that cannot be converted to int
Traceback (most recent call last):
  File "c:\Users\User\OneDrive\שולחן העבודה\My assistant project\my_assistant\clients.py", line 609, in send_link
    client_number = int(update.message.text) - 1
                    ^^^^^^^^^^^^^^^^^^^^^^^^
ValueError: invalid literal for int() with base 10: 'g6'
2023-12-19 13:13:33,992 - clients_logger - ERROR - user send number that is bigger than the clients list length
Traceback (most recent call last):
  File "c:\Users\User\OneDrive\שולחן העבודה\My assistant project\my_assistant\clients.py", line 614, in send_link
    raise IndexOfClientIsTooBig()
exceptions.IndexOfClientIsTooBig: הקלדת מספר גדול מידיי שלא נמצא ברשימת הלקוחות, אנא הקלד מספר תקין.
2023-12-19 13:13:40,107 - clients_logger - ERROR - user send number that is bigger than the clients list length
Traceback (most recent call last):
  File "c:\Users\User\OneDrive\שולחן העבודה\My assistant project\my_assistant\clients.py", line 614, in send_link
    raise IndexOfClientIsTooBig()
exceptions.IndexOfClientIsTooBig: הקלדת מספר גדול מידיי שלא נמצא ברשימת הלקוחות, אנא הקלד מספר תקין.
2023-12-19 13:13:43,355 - clients_logger - ERROR - user send client number to ass debt that cannot be converted to int
Traceback (most recent call last):
  File "c:\Users\User\OneDrive\שולחן העבודה\My assistant project\my_assistant\clients.py", line 609, in send_link
    client_number = int(update.message.text) - 1
                    ^^^^^^^^^^^^^^^^^^^^^^^^
ValueError: invalid literal for int() with base 10: '14g'
2023-12-19 13:14:01,325 - main_logger - INFO - Bot started! Connecting to DB...
2023-12-19 13:14:03,307 - main_logger - INFO - Connected to DB
2023-12-19 13:24:53,628 - main_logger - INFO - Bot started! Connecting to DB...
2023-12-19 13:24:56,040 - main_logger - INFO - Connected to DB
2023-12-19 13:25:02,719 - clients_logger - ERROR - user send client number to ass debt that cannot be converted to int
Traceback (most recent call last):
  File "c:\Users\User\OneDrive\שולחן העבודה\My assistant project\my_assistant\clients.py", line 456, in ask_amount_to_delete
    client_number = int(update.message.text) - 1
                    ^^^^^^^^^^^^^^^^^^^^^^^^
ValueError: invalid literal for int() with base 10: 'g6'
2023-12-19 13:25:07,422 - clients_logger - ERROR - user send number that is bigger than the clients list length
Traceback (most recent call last):
  File "c:\Users\User\OneDrive\שולחן העבודה\My assistant project\my_assistant\clients.py", line 466, in ask_amount_to_delete
    raise IndexOfClientIsTooBig()
exceptions.IndexOfClientIsTooBig: הקלדת מספר גדול מידיי שלא נמצא ברשימת הלקוחות, אנא הקלד מספר תקין.
2023-12-19 13:25:17,749 - clients_logger - ERROR - the user send something that cannot be converted to int
Traceback (most recent call last):
  File "c:\Users\User\OneDrive\שולחן העבודה\My assistant project\my_assistant\clients.py", line 560, in delete_part_debt
    debt_to_delete = int(update.message.text)
                     ^^^^^^^^^^^^^^^^^^^^^^^^
ValueError: invalid literal for int() with base 10: 'fr5'
2023-12-19 13:25:23,425 - clients_logger - ERROR - user send number that is bigger than the clients list length
Traceback (most recent call last):
  File "c:\Users\User\OneDrive\שולחן העבודה\My assistant project\my_assistant\clients.py", line 466, in ask_amount_to_delete
    raise IndexOfClientIsTooBig()
exceptions.IndexOfClientIsTooBig: הקלדת מספר גדול מידיי שלא נמצא ברשימת הלקוחות, אנא הקלד מספר תקין.
2023-12-19 13:37:09,973 - main_logger - INFO - Bot started! Connecting to DB...
2023-12-19 13:37:11,685 - main_logger - INFO - Connected to DB
2023-12-19 13:37:29,467 - clients_logger - ERROR - user send client number to ass debt that cannot be converted to int
Traceback (most recent call last):
  File "c:\Users\User\OneDrive\שולחן העבודה\My assistant project\my_assistant\clients.py", line 456, in ask_amount_to_delete
    client_number = int(update.message.text) - 1
                    ^^^^^^^^^^^^^^^^^^^^^^^^
ValueError: invalid literal for int() with base 10: 'כר5'
2023-12-19 13:37:40,846 - clients_logger - ERROR - user send number that is bigger than the clients list length
Traceback (most recent call last):
  File "c:\Users\User\OneDrive\שולחן העבודה\My assistant project\my_assistant\clients.py", line 466, in ask_amount_to_delete
    raise IndexOfClientIsTooBig()
exceptions.IndexOfClientIsTooBig: הקלדת מספר גדול מידיי שלא נמצא ברשימת הלקוחות, אנא הקלד מספר תקין.
2023-12-19 13:38:06,672 - clients_logger - ERROR - the user send something that cannot be converted to int
Traceback (most recent call last):
  File "c:\Users\User\OneDrive\שולחן העבודה\My assistant project\my_assistant\clients.py", line 560, in delete_part_debt
    debt_to_delete = int(update.message.text)
                     ^^^^^^^^^^^^^^^^^^^^^^^^
ValueError: invalid literal for int() with base 10: 'ערא5'
2023-12-19 13:59:40,701 - main_logger - INFO - Bot started! Connecting to DB...
2023-12-19 13:59:41,963 - main_logger - INFO - Connected to DB
2023-12-19 14:04:22,009 - clients_logger - ERROR - user send client number to ass debt that cannot be converted to int
Traceback (most recent call last):
  File "c:\Users\User\OneDrive\שולחן העבודה\My assistant project\my_assistant\clients.py", line 357, in debt_amount_to_add
    client_number_to_add_debt = int(update.message.text) - 1
                                ^^^^^^^^^^^^^^^^^^^^^^^^
ValueError: invalid literal for int() with base 10: '13.5'
2023-12-19 14:09:18,304 - main_logger - INFO - Bot started! Connecting to DB...
2023-12-19 14:09:19,604 - main_logger - INFO - Connected to DB
2023-12-19 14:21:38,321 - main_logger - INFO - Bot started! Connecting to DB...
2023-12-19 14:21:39,652 - main_logger - INFO - Connected to DB
2023-12-19 14:22:54,560 - clients_logger - ERROR - Can't parse entities: can't find end of the entity starting at byte offset 216
Traceback (most recent call last):
  File "c:\Users\User\OneDrive\שולחן העבודה\My assistant project\my_assistant\clients.py", line 140, in show_clients_callback
    await update.callback_query.message.reply_text(text="*רשימת לקוחות:*\n" + clients_list_text, parse_mode="markdown")
  File "C:\Users\User\OneDrive\שולחן העבודה\My assistant project\venv\Lib\site-packages\telegram\_message.py", line 1094, in reply_text
    return await self.get_bot().send_message(
           ^^^^^^^^^^^^^^^^^^^^^^^^^^^^^^^^^^
  File "C:\Users\User\OneDrive\שולחן העבודה\My assistant project\venv\Lib\site-packages\telegram\ext\_extbot.py", line 2624, in send_message
    return await super().send_message(
           ^^^^^^^^^^^^^^^^^^^^^^^^^^^
  File "C:\Users\User\OneDrive\שולחן העבודה\My assistant project\venv\Lib\site-packages\telegram\_bot.py", line 525, in decorator
    result = await func(self, *args, **kwargs)  # skipcq: PYL-E1102
             ^^^^^^^^^^^^^^^^^^^^^^^^^^^^^^^^^
  File "C:\Users\User\OneDrive\שולחן העבודה\My assistant project\venv\Lib\site-packages\telegram\_bot.py", line 846, in send_message
    return await self._send_message(
           ^^^^^^^^^^^^^^^^^^^^^^^^^
  File "C:\Users\User\OneDrive\שולחן העבודה\My assistant project\venv\Lib\site-packages\telegram\ext\_extbot.py", line 522, in _send_message
    result = await super()._send_message(
             ^^^^^^^^^^^^^^^^^^^^^^^^^^^^
  File "C:\Users\User\OneDrive\שולחן העבודה\My assistant project\venv\Lib\site-packages\telegram\_bot.py", line 703, in _send_message
    result = await self._post(
             ^^^^^^^^^^^^^^^^^
  File "C:\Users\User\OneDrive\שולחן העבודה\My assistant project\venv\Lib\site-packages\telegram\_bot.py", line 613, in _post
    return await self._do_post(
           ^^^^^^^^^^^^^^^^^^^^
  File "C:\Users\User\OneDrive\שולחן העבודה\My assistant project\venv\Lib\site-packages\telegram\ext\_extbot.py", line 340, in _do_post
    return await super()._do_post(
           ^^^^^^^^^^^^^^^^^^^^^^^
  File "C:\Users\User\OneDrive\שולחן העבודה\My assistant project\venv\Lib\site-packages\telegram\_bot.py", line 641, in _do_post
    return await request.post(
           ^^^^^^^^^^^^^^^^^^^
  File "C:\Users\User\OneDrive\שולחן העבודה\My assistant project\venv\Lib\site-packages\telegram\request\_baserequest.py", line 200, in post
    result = await self._request_wrapper(
             ^^^^^^^^^^^^^^^^^^^^^^^^^^^^
  File "C:\Users\User\OneDrive\שולחן העבודה\My assistant project\venv\Lib\site-packages\telegram\request\_baserequest.py", line 379, in _request_wrapper
    raise BadRequest(message)
telegram.error.BadRequest: Can't parse entities: can't find end of the entity starting at byte offset 216
2023-12-19 14:26:56,350 - main_logger - INFO - Bot started! Connecting to DB...
2023-12-19 14:26:57,615 - main_logger - INFO - Connected to DB
2023-12-19 14:27:05,936 - clients_logger - ERROR - Can't parse entities: can't find end of the entity starting at byte offset 216
Traceback (most recent call last):
  File "c:\Users\User\OneDrive\שולחן העבודה\My assistant project\my_assistant\clients.py", line 141, in show_clients_callback
    await update.callback_query.message.reply_text(text="*רשימת לקוחות:*\n" + clients_list_text, parse_mode="markdown")
  File "C:\Users\User\OneDrive\שולחן העבודה\My assistant project\venv\Lib\site-packages\telegram\_message.py", line 1094, in reply_text
    return await self.get_bot().send_message(
           ^^^^^^^^^^^^^^^^^^^^^^^^^^^^^^^^^^
  File "C:\Users\User\OneDrive\שולחן העבודה\My assistant project\venv\Lib\site-packages\telegram\ext\_extbot.py", line 2624, in send_message
    return await super().send_message(
           ^^^^^^^^^^^^^^^^^^^^^^^^^^^
  File "C:\Users\User\OneDrive\שולחן העבודה\My assistant project\venv\Lib\site-packages\telegram\_bot.py", line 525, in decorator
    result = await func(self, *args, **kwargs)  # skipcq: PYL-E1102
             ^^^^^^^^^^^^^^^^^^^^^^^^^^^^^^^^^
  File "C:\Users\User\OneDrive\שולחן העבודה\My assistant project\venv\Lib\site-packages\telegram\_bot.py", line 846, in send_message
    return await self._send_message(
           ^^^^^^^^^^^^^^^^^^^^^^^^^
  File "C:\Users\User\OneDrive\שולחן העבודה\My assistant project\venv\Lib\site-packages\telegram\ext\_extbot.py", line 522, in _send_message
    result = await super()._send_message(
             ^^^^^^^^^^^^^^^^^^^^^^^^^^^^
  File "C:\Users\User\OneDrive\שולחן העבודה\My assistant project\venv\Lib\site-packages\telegram\_bot.py", line 703, in _send_message
    result = await self._post(
             ^^^^^^^^^^^^^^^^^
  File "C:\Users\User\OneDrive\שולחן העבודה\My assistant project\venv\Lib\site-packages\telegram\_bot.py", line 613, in _post
    return await self._do_post(
           ^^^^^^^^^^^^^^^^^^^^
  File "C:\Users\User\OneDrive\שולחן העבודה\My assistant project\venv\Lib\site-packages\telegram\ext\_extbot.py", line 340, in _do_post
    return await super()._do_post(
           ^^^^^^^^^^^^^^^^^^^^^^^
  File "C:\Users\User\OneDrive\שולחן העבודה\My assistant project\venv\Lib\site-packages\telegram\_bot.py", line 641, in _do_post
    return await request.post(
           ^^^^^^^^^^^^^^^^^^^
  File "C:\Users\User\OneDrive\שולחן העבודה\My assistant project\venv\Lib\site-packages\telegram\request\_baserequest.py", line 200, in post
    result = await self._request_wrapper(
             ^^^^^^^^^^^^^^^^^^^^^^^^^^^^
  File "C:\Users\User\OneDrive\שולחן העבודה\My assistant project\venv\Lib\site-packages\telegram\request\_baserequest.py", line 379, in _request_wrapper
    raise BadRequest(message)
telegram.error.BadRequest: Can't parse entities: can't find end of the entity starting at byte offset 216
2023-12-19 14:40:39,072 - main_logger - INFO - Bot started! Connecting to DB...
2023-12-19 14:40:40,852 - main_logger - INFO - Connected to DB
2023-12-19 14:40:49,049 - clients_logger - ERROR - Can't parse entities: character '.' is reserved and must be escaped with the preceding '\'
Traceback (most recent call last):
  File "c:\Users\User\OneDrive\שולחן העבודה\My assistant project\my_assistant\clients.py", line 141, in show_clients_callback
    await update.callback_query.message.reply_text(text="*רשימת לקוחות:*\n" + clients_list_text, parse_mode="markdownV2")
  File "C:\Users\User\OneDrive\שולחן העבודה\My assistant project\venv\Lib\site-packages\telegram\_message.py", line 1094, in reply_text
    return await self.get_bot().send_message(
           ^^^^^^^^^^^^^^^^^^^^^^^^^^^^^^^^^^
  File "C:\Users\User\OneDrive\שולחן העבודה\My assistant project\venv\Lib\site-packages\telegram\ext\_extbot.py", line 2624, in send_message
    return await super().send_message(
           ^^^^^^^^^^^^^^^^^^^^^^^^^^^
  File "C:\Users\User\OneDrive\שולחן העבודה\My assistant project\venv\Lib\site-packages\telegram\_bot.py", line 525, in decorator
    result = await func(self, *args, **kwargs)  # skipcq: PYL-E1102
             ^^^^^^^^^^^^^^^^^^^^^^^^^^^^^^^^^
  File "C:\Users\User\OneDrive\שולחן העבודה\My assistant project\venv\Lib\site-packages\telegram\_bot.py", line 846, in send_message
    return await self._send_message(
           ^^^^^^^^^^^^^^^^^^^^^^^^^
  File "C:\Users\User\OneDrive\שולחן העבודה\My assistant project\venv\Lib\site-packages\telegram\ext\_extbot.py", line 522, in _send_message
    result = await super()._send_message(
             ^^^^^^^^^^^^^^^^^^^^^^^^^^^^
  File "C:\Users\User\OneDrive\שולחן העבודה\My assistant project\venv\Lib\site-packages\telegram\_bot.py", line 703, in _send_message
    result = await self._post(
             ^^^^^^^^^^^^^^^^^
  File "C:\Users\User\OneDrive\שולחן העבודה\My assistant project\venv\Lib\site-packages\telegram\_bot.py", line 613, in _post
    return await self._do_post(
           ^^^^^^^^^^^^^^^^^^^^
  File "C:\Users\User\OneDrive\שולחן העבודה\My assistant project\venv\Lib\site-packages\telegram\ext\_extbot.py", line 340, in _do_post
    return await super()._do_post(
           ^^^^^^^^^^^^^^^^^^^^^^^
  File "C:\Users\User\OneDrive\שולחן העבודה\My assistant project\venv\Lib\site-packages\telegram\_bot.py", line 641, in _do_post
    return await request.post(
           ^^^^^^^^^^^^^^^^^^^
  File "C:\Users\User\OneDrive\שולחן העבודה\My assistant project\venv\Lib\site-packages\telegram\request\_baserequest.py", line 200, in post
    result = await self._request_wrapper(
             ^^^^^^^^^^^^^^^^^^^^^^^^^^^^
  File "C:\Users\User\OneDrive\שולחן העבודה\My assistant project\venv\Lib\site-packages\telegram\request\_baserequest.py", line 379, in _request_wrapper
    raise BadRequest(message)
telegram.error.BadRequest: Can't parse entities: character '.' is reserved and must be escaped with the preceding '\'
2023-12-19 14:40:49,826 - clients_logger - ERROR - Can't parse entities: character '.' is reserved and must be escaped with the preceding '\'
Traceback (most recent call last):
  File "c:\Users\User\OneDrive\שולחן העבודה\My assistant project\my_assistant\clients.py", line 141, in show_clients_callback
    await update.callback_query.message.reply_text(text="*רשימת לקוחות:*\n" + clients_list_text, parse_mode="markdownV2")
  File "C:\Users\User\OneDrive\שולחן העבודה\My assistant project\venv\Lib\site-packages\telegram\_message.py", line 1094, in reply_text
    return await self.get_bot().send_message(
           ^^^^^^^^^^^^^^^^^^^^^^^^^^^^^^^^^^
  File "C:\Users\User\OneDrive\שולחן העבודה\My assistant project\venv\Lib\site-packages\telegram\ext\_extbot.py", line 2624, in send_message
    return await super().send_message(
           ^^^^^^^^^^^^^^^^^^^^^^^^^^^
  File "C:\Users\User\OneDrive\שולחן העבודה\My assistant project\venv\Lib\site-packages\telegram\_bot.py", line 525, in decorator
    result = await func(self, *args, **kwargs)  # skipcq: PYL-E1102
             ^^^^^^^^^^^^^^^^^^^^^^^^^^^^^^^^^
  File "C:\Users\User\OneDrive\שולחן העבודה\My assistant project\venv\Lib\site-packages\telegram\_bot.py", line 846, in send_message
    return await self._send_message(
           ^^^^^^^^^^^^^^^^^^^^^^^^^
  File "C:\Users\User\OneDrive\שולחן העבודה\My assistant project\venv\Lib\site-packages\telegram\ext\_extbot.py", line 522, in _send_message
    result = await super()._send_message(
             ^^^^^^^^^^^^^^^^^^^^^^^^^^^^
  File "C:\Users\User\OneDrive\שולחן העבודה\My assistant project\venv\Lib\site-packages\telegram\_bot.py", line 703, in _send_message
    result = await self._post(
             ^^^^^^^^^^^^^^^^^
  File "C:\Users\User\OneDrive\שולחן העבודה\My assistant project\venv\Lib\site-packages\telegram\_bot.py", line 613, in _post
    return await self._do_post(
           ^^^^^^^^^^^^^^^^^^^^
  File "C:\Users\User\OneDrive\שולחן העבודה\My assistant project\venv\Lib\site-packages\telegram\ext\_extbot.py", line 340, in _do_post
    return await super()._do_post(
           ^^^^^^^^^^^^^^^^^^^^^^^
  File "C:\Users\User\OneDrive\שולחן העבודה\My assistant project\venv\Lib\site-packages\telegram\_bot.py", line 641, in _do_post
    return await request.post(
           ^^^^^^^^^^^^^^^^^^^
  File "C:\Users\User\OneDrive\שולחן העבודה\My assistant project\venv\Lib\site-packages\telegram\request\_baserequest.py", line 200, in post
    result = await self._request_wrapper(
             ^^^^^^^^^^^^^^^^^^^^^^^^^^^^
  File "C:\Users\User\OneDrive\שולחן העבודה\My assistant project\venv\Lib\site-packages\telegram\request\_baserequest.py", line 379, in _request_wrapper
    raise BadRequest(message)
telegram.error.BadRequest: Can't parse entities: character '.' is reserved and must be escaped with the preceding '\'
2023-12-19 14:53:37,182 - main_logger - INFO - Bot started! Connecting to DB...
2023-12-19 14:53:39,199 - main_logger - INFO - Connected to DB
2023-12-19 14:53:44,080 - clients_logger - ERROR - Can't parse entities: can't find end of the entity starting at byte offset 216
Traceback (most recent call last):
  File "c:\Users\User\OneDrive\שולחן העבודה\My assistant project\my_assistant\clients.py", line 146, in show_clients_callback
    await update.callback_query.message.reply_text(text="*רשימת לקוחות:*\n" + clients_list_text, parse_mode="markdown")
  File "C:\Users\User\OneDrive\שולחן העבודה\My assistant project\venv\Lib\site-packages\telegram\_message.py", line 1094, in reply_text
    return await self.get_bot().send_message(
           ^^^^^^^^^^^^^^^^^^^^^^^^^^^^^^^^^^
  File "C:\Users\User\OneDrive\שולחן העבודה\My assistant project\venv\Lib\site-packages\telegram\ext\_extbot.py", line 2624, in send_message
    return await super().send_message(
           ^^^^^^^^^^^^^^^^^^^^^^^^^^^
  File "C:\Users\User\OneDrive\שולחן העבודה\My assistant project\venv\Lib\site-packages\telegram\_bot.py", line 525, in decorator
    result = await func(self, *args, **kwargs)  # skipcq: PYL-E1102
             ^^^^^^^^^^^^^^^^^^^^^^^^^^^^^^^^^
  File "C:\Users\User\OneDrive\שולחן העבודה\My assistant project\venv\Lib\site-packages\telegram\_bot.py", line 846, in send_message
    return await self._send_message(
           ^^^^^^^^^^^^^^^^^^^^^^^^^
  File "C:\Users\User\OneDrive\שולחן העבודה\My assistant project\venv\Lib\site-packages\telegram\ext\_extbot.py", line 522, in _send_message
    result = await super()._send_message(
             ^^^^^^^^^^^^^^^^^^^^^^^^^^^^
  File "C:\Users\User\OneDrive\שולחן העבודה\My assistant project\venv\Lib\site-packages\telegram\_bot.py", line 703, in _send_message
    result = await self._post(
             ^^^^^^^^^^^^^^^^^
  File "C:\Users\User\OneDrive\שולחן העבודה\My assistant project\venv\Lib\site-packages\telegram\_bot.py", line 613, in _post
    return await self._do_post(
           ^^^^^^^^^^^^^^^^^^^^
  File "C:\Users\User\OneDrive\שולחן העבודה\My assistant project\venv\Lib\site-packages\telegram\ext\_extbot.py", line 340, in _do_post
    return await super()._do_post(
           ^^^^^^^^^^^^^^^^^^^^^^^
  File "C:\Users\User\OneDrive\שולחן העבודה\My assistant project\venv\Lib\site-packages\telegram\_bot.py", line 641, in _do_post
    return await request.post(
           ^^^^^^^^^^^^^^^^^^^
  File "C:\Users\User\OneDrive\שולחן העבודה\My assistant project\venv\Lib\site-packages\telegram\request\_baserequest.py", line 200, in post
    result = await self._request_wrapper(
             ^^^^^^^^^^^^^^^^^^^^^^^^^^^^
  File "C:\Users\User\OneDrive\שולחן העבודה\My assistant project\venv\Lib\site-packages\telegram\request\_baserequest.py", line 379, in _request_wrapper
    raise BadRequest(message)
telegram.error.BadRequest: Can't parse entities: can't find end of the entity starting at byte offset 216
2023-12-19 14:54:29,520 - main_logger - INFO - Bot started! Connecting to DB...
2023-12-19 14:54:31,193 - main_logger - INFO - Connected to DB
2023-12-19 15:03:04,347 - main_logger - INFO - Bot started! Connecting to DB...
2023-12-19 15:03:06,278 - main_logger - INFO - Connected to DB
2023-12-19 15:03:30,219 - clients_logger - ERROR - user send number that is bigger than the clients list length
Traceback (most recent call last):
  File "c:\Users\User\OneDrive\שולחן העבודה\My assistant project\my_assistant\clients.py", line 371, in debt_amount_to_add
    raise IndexOfClientIsOutOfRange()
exceptions.IndexOfClientIsOutOfRange: הקלדת מספר שלא נמצא ברשימת הלקוחות, אנא הקלד מספר תקין.
2023-12-19 15:03:34,827 - clients_logger - ERROR - user send number that is bigger than the clients list length
Traceback (most recent call last):
  File "c:\Users\User\OneDrive\שולחן העבודה\My assistant project\my_assistant\clients.py", line 371, in debt_amount_to_add
    raise IndexOfClientIsOutOfRange()
exceptions.IndexOfClientIsOutOfRange: הקלדת מספר שלא נמצא ברשימת הלקוחות, אנא הקלד מספר תקין.
2023-12-19 15:03:39,742 - clients_logger - ERROR - user send number that is bigger than the clients list length
Traceback (most recent call last):
  File "c:\Users\User\OneDrive\שולחן העבודה\My assistant project\my_assistant\clients.py", line 371, in debt_amount_to_add
    raise IndexOfClientIsOutOfRange()
exceptions.IndexOfClientIsOutOfRange: הקלדת מספר שלא נמצא ברשימת הלקוחות, אנא הקלד מספר תקין.
2023-12-19 15:03:47,014 - clients_logger - ERROR - user send client number to ass debt that cannot be converted to int
Traceback (most recent call last):
  File "c:\Users\User\OneDrive\שולחן העבודה\My assistant project\my_assistant\clients.py", line 368, in debt_amount_to_add
    client_number_to_add_debt = int(update.message.text) - 1
                                ^^^^^^^^^^^^^^^^^^^^^^^^
ValueError: invalid literal for int() with base 10: 'Bdhs7'
2023-12-19 15:07:50,565 - main_logger - INFO - Bot started! Connecting to DB...
2023-12-19 15:07:52,287 - main_logger - INFO - Connected to DB
2023-12-19 15:08:01,782 - clients_logger - ERROR - user send number that is bigger than the clients list length
Traceback (most recent call last):
  File "c:\Users\User\OneDrive\שולחן העבודה\My assistant project\my_assistant\clients.py", line 477, in ask_amount_to_delete
    raise IndexOfClientIsOutOfRange()
exceptions.IndexOfClientIsOutOfRange: הקלדת מספר שלא נמצא ברשימת הלקוחות, אנא הקלד מספר תקין.
2023-12-19 15:08:06,263 - clients_logger - ERROR - user send number that is bigger than the clients list length
Traceback (most recent call last):
  File "c:\Users\User\OneDrive\שולחן העבודה\My assistant project\my_assistant\clients.py", line 477, in ask_amount_to_delete
    raise IndexOfClientIsOutOfRange()
exceptions.IndexOfClientIsOutOfRange: הקלדת מספר שלא נמצא ברשימת הלקוחות, אנא הקלד מספר תקין.
2023-12-19 15:08:09,175 - clients_logger - ERROR - user send number that is bigger than the clients list length
Traceback (most recent call last):
  File "c:\Users\User\OneDrive\שולחן העבודה\My assistant project\my_assistant\clients.py", line 477, in ask_amount_to_delete
    raise IndexOfClientIsOutOfRange()
exceptions.IndexOfClientIsOutOfRange: הקלדת מספר שלא נמצא ברשימת הלקוחות, אנא הקלד מספר תקין.
2023-12-19 15:09:11,652 - clients_logger - ERROR - the user send something that cannot be converted to int
Traceback (most recent call last):
  File "c:\Users\User\OneDrive\שולחן העבודה\My assistant project\my_assistant\clients.py", line 571, in delete_part_debt
    debt_to_delete = int(update.message.text)
                     ^^^^^^^^^^^^^^^^^^^^^^^^
ValueError: invalid literal for int() with base 10: 'כוע5'
2023-12-19 15:14:27,263 - main_logger - INFO - Bot started! Connecting to DB...
2023-12-19 15:14:29,211 - main_logger - INFO - Connected to DB
2023-12-19 15:15:02,774 - clients_logger - ERROR - user send number that is bigger than the clients list length
Traceback (most recent call last):
  File "c:\Users\User\OneDrive\שולחן העבודה\My assistant project\my_assistant\clients.py", line 477, in ask_amount_to_delete
    raise IndexOfClientIsOutOfRange()
exceptions.IndexOfClientIsOutOfRange: הקלדת מספר שלא נמצא ברשימת הלקוחות, אנא הקלד מספר תקין.
2023-12-19 15:15:54,043 - clients_logger - ERROR - the user send negative number of debt to delete
Traceback (most recent call last):
  File "c:\Users\User\OneDrive\שולחן העבודה\My assistant project\my_assistant\clients.py", line 574, in delete_part_debt
    raise DebtToDeleteIsNegative()
exceptions.DebtToDeleteIsNegative: לא ניתן להוריד חוב שמספרו שלילי, אנא הזן מספר חיובי.
2023-12-19 15:21:39,628 - main_logger - INFO - Bot started! Connecting to DB...
2023-12-19 15:21:42,043 - main_logger - INFO - Connected to DB
2023-12-19 15:28:48,082 - main_logger - INFO - Bot started! Connecting to DB...
2023-12-19 15:28:50,084 - main_logger - INFO - Connected to DB
2023-12-19 15:29:46,529 - main_logger - INFO - Bot started! Connecting to DB...
2023-12-19 15:29:48,043 - main_logger - INFO - Connected to DB
2023-12-20 12:07:36,484 - main_logger - INFO - Bot started! Connecting to DB...
2023-12-20 12:07:38,419 - main_logger - INFO - Connected to DB
2023-12-20 12:08:27,942 - main_logger - INFO - Bot started! Connecting to DB...
2023-12-20 12:08:29,273 - main_logger - INFO - Connected to DB
2023-12-20 12:09:24,690 - main_logger - INFO - Bot started! Connecting to DB...
2023-12-20 12:09:26,523 - main_logger - INFO - Connected to DB
2023-12-20 12:10:29,297 - main_logger - INFO - Bot started! Connecting to DB...
2023-12-20 12:10:31,066 - main_logger - INFO - Connected to DB
2023-12-20 12:21:29,856 - main_logger - INFO - Bot started! Connecting to DB...
2023-12-20 12:21:31,556 - main_logger - INFO - Connected to DB
2023-12-20 12:22:37,328 - main_logger - INFO - Bot started! Connecting to DB...
2023-12-20 12:22:38,968 - main_logger - INFO - Connected to DB
2023-12-20 13:43:37,129 - main_logger - INFO - Bot started! Connecting to DB...
2023-12-20 13:43:39,086 - main_logger - INFO - Connected to DB
2023-12-20 13:44:30,525 - main_logger - INFO - Bot started! Connecting to DB...
2023-12-20 13:44:31,855 - main_logger - INFO - Connected to DB
2023-12-20 14:31:27,053 - main_logger - INFO - Bot started! Connecting to DB...
2023-12-20 14:31:28,908 - main_logger - INFO - Connected to DB
2023-12-23 09:46:59,566 - main_logger - INFO - Bot started! Connecting to DB...
2023-12-23 09:47:01,172 - main_logger - INFO - Connected to DB
2023-12-23 09:50:05,563 - main_logger - INFO - Bot started! Connecting to DB...
2023-12-23 09:50:07,401 - main_logger - INFO - Connected to DB
2023-12-23 09:51:23,275 - main_logger - INFO - Bot started! Connecting to DB...
2023-12-23 09:51:25,124 - main_logger - INFO - Connected to DB
2023-12-23 09:52:19,066 - main_logger - INFO - Bot started! Connecting to DB...
2023-12-23 09:52:20,819 - main_logger - INFO - Connected to DB
2023-12-23 09:54:45,583 - main_logger - INFO - Bot started! Connecting to DB...
2023-12-23 09:54:47,192 - main_logger - INFO - Connected to DB
2023-12-23 09:55:38,867 - main_logger - INFO - Bot started! Connecting to DB...
2023-12-23 09:55:40,512 - main_logger - INFO - Connected to DB
2023-12-23 09:56:12,348 - main_logger - INFO - Bot started! Connecting to DB...
2023-12-23 09:56:13,792 - main_logger - INFO - Connected to DB
2023-12-23 09:57:32,160 - main_logger - INFO - Bot started! Connecting to DB...
2023-12-23 09:57:33,754 - main_logger - INFO - Connected to DB
2023-12-23 09:59:27,478 - main_logger - INFO - Bot started! Connecting to DB...
2023-12-23 09:59:29,014 - main_logger - INFO - Connected to DB
2023-12-23 10:58:23,220 - main_logger - INFO - Bot started! Connecting to DB...
2023-12-23 10:58:24,846 - main_logger - INFO - Connected to DB
2023-12-23 11:03:19,476 - main_logger - INFO - Bot started! Connecting to DB...
2023-12-23 11:03:21,217 - main_logger - INFO - Connected to DB
2023-12-23 11:04:18,401 - todolist_logger - ERROR - Can't parse entities: can't find end tag corresponding to start tag b
Traceback (most recent call last):
  File "c:\Users\User\OneDrive\שולחן העבודה\My assistant project\my_assistant\todolist.py", line 100, in add_task
    await update.callback_query.message.reply_text(text=f"המשימה: <b>{user_data_add_task["task"]}</b> נוספה בהצלחה לקטגוריה: <b>{user_data_add_task["category"]}</b>", reply_markup=reply_markup, parse_mode='HTML')
  File "C:\Users\User\OneDrive\שולחן העבודה\My assistant project\venv\Lib\site-packages\telegram\_message.py", line 1094, in reply_text
    return await self.get_bot().send_message(
           ^^^^^^^^^^^^^^^^^^^^^^^^^^^^^^^^^^
  File "C:\Users\User\OneDrive\שולחן העבודה\My assistant project\venv\Lib\site-packages\telegram\ext\_extbot.py", line 2624, in send_message
    return await super().send_message(
           ^^^^^^^^^^^^^^^^^^^^^^^^^^^
  File "C:\Users\User\OneDrive\שולחן העבודה\My assistant project\venv\Lib\site-packages\telegram\_bot.py", line 525, in decorator
    result = await func(self, *args, **kwargs)  # skipcq: PYL-E1102
             ^^^^^^^^^^^^^^^^^^^^^^^^^^^^^^^^^
  File "C:\Users\User\OneDrive\שולחן העבודה\My assistant project\venv\Lib\site-packages\telegram\_bot.py", line 846, in send_message
    return await self._send_message(
           ^^^^^^^^^^^^^^^^^^^^^^^^^
  File "C:\Users\User\OneDrive\שולחן העבודה\My assistant project\venv\Lib\site-packages\telegram\ext\_extbot.py", line 522, in _send_message
    result = await super()._send_message(
             ^^^^^^^^^^^^^^^^^^^^^^^^^^^^
  File "C:\Users\User\OneDrive\שולחן העבודה\My assistant project\venv\Lib\site-packages\telegram\_bot.py", line 703, in _send_message
    result = await self._post(
             ^^^^^^^^^^^^^^^^^
  File "C:\Users\User\OneDrive\שולחן העבודה\My assistant project\venv\Lib\site-packages\telegram\_bot.py", line 613, in _post
    return await self._do_post(
           ^^^^^^^^^^^^^^^^^^^^
  File "C:\Users\User\OneDrive\שולחן העבודה\My assistant project\venv\Lib\site-packages\telegram\ext\_extbot.py", line 340, in _do_post
    return await super()._do_post(
           ^^^^^^^^^^^^^^^^^^^^^^^
  File "C:\Users\User\OneDrive\שולחן העבודה\My assistant project\venv\Lib\site-packages\telegram\_bot.py", line 641, in _do_post
    return await request.post(
           ^^^^^^^^^^^^^^^^^^^
  File "C:\Users\User\OneDrive\שולחן העבודה\My assistant project\venv\Lib\site-packages\telegram\request\_baserequest.py", line 200, in post
    result = await self._request_wrapper(
             ^^^^^^^^^^^^^^^^^^^^^^^^^^^^
  File "C:\Users\User\OneDrive\שולחן העבודה\My assistant project\venv\Lib\site-packages\telegram\request\_baserequest.py", line 379, in _request_wrapper
    raise BadRequest(message)
telegram.error.BadRequest: Can't parse entities: can't find end tag corresponding to start tag b
2023-12-23 11:07:22,544 - main_logger - INFO - Bot started! Connecting to DB...
2023-12-23 11:07:24,318 - main_logger - INFO - Connected to DB
2023-12-23 11:13:15,081 - main_logger - INFO - Bot started! Connecting to DB...
2023-12-23 11:13:16,985 - main_logger - INFO - Connected to DB
2023-12-23 11:16:26,956 - main_logger - INFO - Bot started! Connecting to DB...
2023-12-23 11:16:28,578 - main_logger - INFO - Connected to DB
2023-12-23 11:18:31,746 - main_logger - INFO - Bot started! Connecting to DB...
2023-12-23 11:18:33,227 - main_logger - INFO - Connected to DB
2023-12-23 11:23:06,480 - main_logger - INFO - Bot started! Connecting to DB...
2023-12-23 11:23:08,279 - main_logger - INFO - Connected to DB
2023-12-23 11:25:54,921 - clients_logger - ERROR - user send client number to a debt that cannot be converted to int
Traceback (most recent call last):
  File "c:\Users\User\OneDrive\שולחן העבודה\My assistant project\my_assistant\clients.py", line 644, in send_link
    client_number = int(update.message.text) - 1
                    ^^^^^^^^^^^^^^^^^^^^^^^^
ValueError: invalid literal for int() with base 10: 'לרוץ'
2023-12-23 11:34:32,883 - main_logger - INFO - Bot started! Connecting to DB...
2023-12-23 11:34:34,810 - main_logger - INFO - Connected to DB
2023-12-23 11:36:29,138 - main_logger - INFO - Bot started! Connecting to DB...
2023-12-23 11:36:30,766 - main_logger - INFO - Connected to DB
2023-12-23 11:37:32,671 - main_logger - INFO - Bot started! Connecting to DB...
2023-12-23 11:37:34,332 - main_logger - INFO - Connected to DB
2023-12-23 11:38:55,611 - main_logger - INFO - Bot started! Connecting to DB...
2023-12-23 11:38:57,069 - main_logger - INFO - Connected to DB
2023-12-23 11:40:57,733 - main_logger - INFO - Bot started! Connecting to DB...
2023-12-23 11:41:00,023 - main_logger - INFO - Connected to DB
2023-12-23 12:22:12,997 - main_logger - INFO - Bot started! Connecting to DB...
2023-12-23 12:22:15,292 - main_logger - INFO - Connected to DB
2023-12-23 12:24:21,817 - main_logger - INFO - Bot started! Connecting to DB...
2023-12-23 12:24:23,905 - main_logger - INFO - Connected to DB
2023-12-23 15:31:32,531 - main_logger - INFO - Bot started! Connecting to DB...
2023-12-23 15:31:33,885 - main_logger - INFO - Connected to DB
2023-12-23 15:36:06,685 - main_logger - INFO - Bot started! Connecting to DB...
2023-12-23 15:36:08,389 - main_logger - INFO - Connected to DB
2023-12-23 15:38:39,151 - main_logger - INFO - Bot started! Connecting to DB...
2023-12-23 15:38:41,313 - main_logger - INFO - Connected to DB
2023-12-23 16:00:57,720 - main_logger - INFO - Bot started! Connecting to DB...
2023-12-23 16:00:59,509 - main_logger - INFO - Connected to DB
2023-12-23 16:43:11,571 - main_logger - INFO - Bot started! Connecting to DB...
2023-12-23 16:43:12,986 - main_logger - INFO - Connected to DB
2023-12-23 16:49:20,543 - main_logger - INFO - Bot started! Connecting to DB...
2023-12-23 16:49:22,542 - main_logger - INFO - Connected to DB
2023-12-23 16:51:57,818 - main_logger - INFO - Bot started! Connecting to DB...
2023-12-23 16:51:59,180 - main_logger - INFO - Connected to DB
2023-12-23 16:53:49,113 - main_logger - INFO - Bot started! Connecting to DB...
2023-12-23 16:53:50,524 - main_logger - INFO - Connected to DB
2023-12-23 16:54:44,856 - main_logger - INFO - Bot started! Connecting to DB...
2023-12-23 16:54:46,951 - main_logger - INFO - Connected to DB
2023-12-23 16:55:46,040 - main_logger - INFO - Bot started! Connecting to DB...
2023-12-23 16:55:47,343 - main_logger - INFO - Connected to DB
2023-12-23 16:56:29,434 - main_logger - INFO - Bot started! Connecting to DB...
2023-12-23 16:56:30,725 - main_logger - INFO - Connected to DB
2023-12-25 10:00:51,488 - main_logger - INFO - Bot started! Connecting to DB...
2023-12-25 10:00:53,307 - main_logger - INFO - Connected to DB
2023-12-25 10:01:41,620 - todolist_logger - ERROR - unable to delete task from the chosen category.
Traceback (most recent call last):
  File "c:\Users\User\OneDrive\שולחן העבודה\My assistant project\my_assistant\todolist.py", line 229, in delete_task
    if task_number + 1 > user_data_delete_task["len_of_category_tasks_list"] or task_number < 0:
                         ~~~~~~~~~~~~~~~~~~~~~^^^^^^^^^^^^^^^^^^^^^^^^^^^^^^
KeyError: 'len_of_category_tasks_list'
2023-12-25 10:04:05,707 - main_logger - INFO - Bot started! Connecting to DB...
2023-12-25 10:04:07,810 - main_logger - INFO - Connected to DB
2023-12-25 10:04:30,749 - todolist_logger - ERROR - unable to delete task from the chosen category.
Traceback (most recent call last):
  File "c:\Users\User\OneDrive\שולחן העבודה\My assistant project\my_assistant\todolist.py", line 229, in delete_task
    if task_number + 1 > user_data_delete_task["len_of_category_tasks_list"] or task_number < 0:
                         ~~~~~~~~~~~~~~~~~~~~~^^^^^^^^^^^^^^^^^^^^^^^^^^^^^^
KeyError: 'len_of_category_tasks_list'
2023-12-25 10:05:29,449 - main_logger - INFO - Bot started! Connecting to DB...
2023-12-25 10:05:31,343 - main_logger - INFO - Connected to DB
2023-12-25 10:05:41,743 - db_connection_logger - ERROR - unable to delete object from db.
2023-12-25 10:05:41,744 - todolist_logger - ERROR - unable to delete task from the chosen category.
Traceback (most recent call last):
  File "C:\Users\User\OneDrive\שולחן העבודה\My assistant project\venv\Lib\site-packages\mysql\connector\connection_cext.py", line 639, in cmd_query
    self._cmysql.query(
_mysql_connector.MySQLInterfaceError: You have an error in your SQL syntax; check the manual that corresponds to your MySQL server version for the right syntax to use near ''to_do_list' WHERE id = 5 AND user_id = 222151854' at line 1

The above exception was the direct cause of the following exception:

Traceback (most recent call last):
  File "c:\Users\User\OneDrive\שולחן העבודה\My assistant project\my_assistant\todolist.py", line 238, in delete_task
    delete_object_from_db(
  File "c:\Users\User\OneDrive\שולחן העבודה\My assistant project\my_assistant\db_connection.py", line 190, in delete_object_from_db
    db_cursor.execute(sql_delete_client, (table_name, object_id, user_id))
  File "C:\Users\User\OneDrive\שולחן העבודה\My assistant project\venv\Lib\site-packages\mysql\connector\cursor_cext.py", line 330, in execute
    result = self._cnx.cmd_query(
             ^^^^^^^^^^^^^^^^^^^^
  File "C:\Users\User\OneDrive\שולחן העבודה\My assistant project\venv\Lib\site-packages\mysql\connector\opentelemetry\context_propagation.py", line 77, in wrapper
    return method(cnx, *args, **kwargs)
           ^^^^^^^^^^^^^^^^^^^^^^^^^^^^
  File "C:\Users\User\OneDrive\שולחן העבודה\My assistant project\venv\Lib\site-packages\mysql\connector\connection_cext.py", line 647, in cmd_query
    raise get_mysql_exception(
mysql.connector.errors.ProgrammingError: 1064 (42000): You have an error in your SQL syntax; check the manual that corresponds to your MySQL server version for the right syntax to use near ''to_do_list' WHERE id = 5 AND user_id = 222151854' at line 1
2023-12-25 10:09:11,439 - main_logger - INFO - Bot started! Connecting to DB...
2023-12-25 10:09:14,188 - main_logger - INFO - Connected to DB
2023-12-25 10:09:56,449 - todolist_logger - ERROR - user send number that is not in the list of tasks
Traceback (most recent call last):
  File "c:\Users\User\OneDrive\שולחן העבודה\My assistant project\my_assistant\todolist.py", line 230, in delete_task
    raise IndexIsOutOfRange()
exceptions.IndexIsOutOfRange: הקלדת מספר שלא נמצא ברשימה, אנא הקלד מספר תקין.
2023-12-25 10:10:02,384 - todolist_logger - ERROR - user send number that is not in the list of tasks
Traceback (most recent call last):
  File "c:\Users\User\OneDrive\שולחן העבודה\My assistant project\my_assistant\todolist.py", line 230, in delete_task
    raise IndexIsOutOfRange()
exceptions.IndexIsOutOfRange: הקלדת מספר שלא נמצא ברשימה, אנא הקלד מספר תקין.
2023-12-25 10:10:08,372 - todolist_logger - ERROR - user send task number to delete that cannot be converted to int
Traceback (most recent call last):
  File "c:\Users\User\OneDrive\שולחן העבודה\My assistant project\my_assistant\todolist.py", line 227, in delete_task
    task_number = int(update.message.text) - 1
                  ^^^^^^^^^^^^^^^^^^^^^^^^
ValueError: invalid literal for int() with base 10: 'vyt6'
2023-12-25 10:10:20,054 - todolist_logger - ERROR - user send number that is not in the list of tasks
Traceback (most recent call last):
  File "c:\Users\User\OneDrive\שולחן העבודה\My assistant project\my_assistant\todolist.py", line 230, in delete_task
    raise IndexIsOutOfRange()
exceptions.IndexIsOutOfRange: הקלדת מספר שלא נמצא ברשימה, אנא הקלד מספר תקין.
2023-12-25 10:10:23,966 - todolist_logger - ERROR - user send task number to delete that cannot be converted to int
Traceback (most recent call last):
  File "c:\Users\User\OneDrive\שולחן העבודה\My assistant project\my_assistant\todolist.py", line 227, in delete_task
    task_number = int(update.message.text) - 1
                  ^^^^^^^^^^^^^^^^^^^^^^^^
ValueError: invalid literal for int() with base 10: 'hbj7'
2023-12-25 10:10:31,913 - todolist_logger - ERROR - user send task number to delete that cannot be converted to int
Traceback (most recent call last):
  File "c:\Users\User\OneDrive\שולחן העבודה\My assistant project\my_assistant\todolist.py", line 227, in delete_task
    task_number = int(update.message.text) - 1
                  ^^^^^^^^^^^^^^^^^^^^^^^^
ValueError: invalid literal for int() with base 10: '1.'
2023-12-25 10:13:10,134 - main_logger - INFO - Bot started! Connecting to DB...
2023-12-25 10:13:12,077 - main_logger - INFO - Connected to DB
2023-12-25 10:13:53,922 - main_logger - INFO - Bot started! Connecting to DB...
2023-12-25 10:13:55,904 - main_logger - INFO - Connected to DB
2023-12-25 10:38:08,744 - main_logger - INFO - Bot started! Connecting to DB...
2023-12-25 10:38:10,645 - main_logger - INFO - Connected to DB
2023-12-25 10:51:34,392 - main_logger - INFO - Bot started! Connecting to DB...
2023-12-25 10:51:36,324 - main_logger - INFO - Connected to DB
2023-12-25 10:52:07,258 - main_logger - INFO - Bot started! Connecting to DB...
2023-12-25 10:52:08,842 - main_logger - INFO - Connected to DB
2023-12-25 10:53:34,513 - main_logger - INFO - Bot started! Connecting to DB...
2023-12-25 10:53:36,122 - main_logger - INFO - Connected to DB
2023-12-25 21:24:42,005 - main_logger - INFO - Bot started! Connecting to DB...
2023-12-25 21:24:45,877 - main_logger - INFO - Connected to DB
