2023-12-17 13:03:10,488 - main_logger - INFO - Bot started! Connecting to DB...
2023-12-17 13:03:12,452 - main_logger - INFO - Connected to DB
2023-12-17 13:06:59,754 - main_logger - INFO - Bot started! Connecting to DB...
2023-12-17 13:07:02,032 - main_logger - INFO - Connected to DB
2023-12-17 13:14:24,249 - main_logger - INFO - Bot started! Connecting to DB...
2023-12-17 13:14:26,134 - main_logger - INFO - Connected to DB
2023-12-17 13:25:21,119 - main_logger - INFO - Bot started! Connecting to DB...
2023-12-17 13:25:22,747 - main_logger - INFO - Connected to DB
2023-12-17 13:32:18,498 - clients_logger - DEBUG - {'user_id': 222151854, 'username': 'גוון ויינברגר', 'full_name': 'בדיקה1', 'address': 'בדיקה'}
2023-12-17 13:37:14,053 - main_logger - INFO - Bot started! Connecting to DB...
2023-12-17 13:37:15,971 - main_logger - INFO - Connected to DB
2023-12-17 13:37:58,371 - clients_logger - DEBUG - {'user_id': 222151854, 'username': 'גוון ויינברגר', 'full_name': 'בדיקה1', 'address': 'בדיקה'}
2023-12-17 13:38:10,092 - db_connection_logger - INFO - user tried to add client that is already in the list
2023-12-17 13:38:10,093 - db_connection_logger - ERROR - unable to add client to data base
2023-12-17 13:41:04,789 - main_logger - INFO - Bot started! Connecting to DB...
2023-12-17 13:41:06,180 - main_logger - INFO - Connected to DB
2023-12-17 13:42:32,704 - clients_logger - DEBUG - {'user_id': 222151854, 'username': 'גוון ויינברגר', 'full_name': 'בדיקה3', 'address': 'בדיקה'}
2023-12-17 13:42:42,840 - clients_logger - DEBUG - {'user_id': 222151854, 'username': 'גוון ויינברגר', 'full_name': 'תבדיקה4', 'address': 'בדיקה'}
2023-12-17 13:44:08,811 - main_logger - INFO - Bot started! Connecting to DB...
2023-12-17 13:44:10,692 - main_logger - INFO - Connected to DB
2023-12-17 14:01:18,437 - main_logger - INFO - Bot started! Connecting to DB...
2023-12-17 14:01:20,446 - main_logger - INFO - Connected to DB
2023-12-17 14:01:37,551 - clients_logger - DEBUG - {'user_id': 222151854, 'username': 'גוון ויינברגר', 'full_name': 'בדיקה1', 'address': 'בדיקה'}
2023-12-17 14:01:50,762 - clients_logger - DEBUG - {'user_id': 222151854, 'username': 'גוון ויינברגר', 'full_name': 'בדיקה2', 'address': 'בדיקה'}
2023-12-17 14:02:16,679 - clients_logger - DEBUG - {'user_id': 222151854, 'username': 'גוון ויינברגר', 'full_name': 'תבדיקה3', 'address': 'בדיקה'}
2023-12-17 14:04:17,045 - main_logger - INFO - Bot started! Connecting to DB...
2023-12-17 14:04:19,444 - main_logger - INFO - Connected to DB
2023-12-17 14:09:52,831 - main_logger - INFO - Bot started! Connecting to DB...
2023-12-17 14:09:55,119 - main_logger - INFO - Connected to DB
2023-12-17 14:13:08,259 - main_logger - INFO - Bot started! Connecting to DB...
2023-12-17 14:13:10,285 - main_logger - INFO - Connected to DB
2023-12-17 14:15:45,733 - main_logger - INFO - Bot started! Connecting to DB...
2023-12-17 14:15:47,787 - main_logger - INFO - Connected to DB
2023-12-17 14:16:21,994 - clients_logger - DEBUG - {'user_id': 222151854, 'username': 'גוון ויינברגר', 'full_name': 'גוון', 'address': 'בדיקה1'}
2023-12-17 14:16:51,077 - clients_logger - DEBUG - {'user_id': 222151854, 'username': 'גוון ויינברגר', 'full_name': 'בדיקה1', 'address': 'בדיקה2'}
2023-12-17 14:21:44,854 - main_logger - INFO - Bot started! Connecting to DB...
2023-12-17 14:21:46,529 - main_logger - INFO - Connected to DB
2023-12-17 14:21:58,130 - clients_logger - DEBUG - {'user_id': 222151854, 'username': 'גוון ויינברגר', 'full_name': 'גוון', 'address': 'ויינברגר'}
2023-12-17 14:22:49,775 - clients_logger - ERROR - can't show buttons with names of client to delete
Traceback (most recent call last):
  File "c:\Users\User\OneDrive\שולחן העבודה\My assistant project\my_assistant\clients.py", line 258, in next_page
    await update.callback_query.message.reply_text(reply_markup=reply_markup, parse_mode='Markdown')
          ^^^^^^^^^^^^^^^^^^^^^^^^^^^^^^^^^^^^^^^^^^^^^^^^^^^^^^^^^^^^^^^^^^^^^^^^^^^^^^^^^^^^^^^^^^
TypeError: Message.reply_text() missing 1 required positional argument: 'text'
2023-12-17 14:24:01,160 - main_logger - INFO - Bot started! Connecting to DB...
2023-12-17 14:24:02,988 - main_logger - INFO - Connected to DB
2023-12-17 14:24:10,550 - clients_logger - ERROR - can't show buttons with names of client to delete
Traceback (most recent call last):
  File "c:\Users\User\OneDrive\שולחן העבודה\My assistant project\my_assistant\clients.py", line 258, in next_page
    await update.callback_query.message.reply_text("", reply_markup=reply_markup, parse_mode='Markdown')
  File "C:\Users\User\OneDrive\שולחן העבודה\My assistant project\venv\Lib\site-packages\telegram\_message.py", line 1094, in reply_text
    return await self.get_bot().send_message(
           ^^^^^^^^^^^^^^^^^^^^^^^^^^^^^^^^^^
  File "C:\Users\User\OneDrive\שולחן העבודה\My assistant project\venv\Lib\site-packages\telegram\ext\_extbot.py", line 2624, in send_message
    return await super().send_message(
           ^^^^^^^^^^^^^^^^^^^^^^^^^^^
  File "C:\Users\User\OneDrive\שולחן העבודה\My assistant project\venv\Lib\site-packages\telegram\_bot.py", line 525, in decorator
    result = await func(self, *args, **kwargs)  # skipcq: PYL-E1102
             ^^^^^^^^^^^^^^^^^^^^^^^^^^^^^^^^^
  File "C:\Users\User\OneDrive\שולחן העבודה\My assistant project\venv\Lib\site-packages\telegram\_bot.py", line 846, in send_message
    return await self._send_message(
           ^^^^^^^^^^^^^^^^^^^^^^^^^
  File "C:\Users\User\OneDrive\שולחן העבודה\My assistant project\venv\Lib\site-packages\telegram\ext\_extbot.py", line 522, in _send_message
    result = await super()._send_message(
             ^^^^^^^^^^^^^^^^^^^^^^^^^^^^
  File "C:\Users\User\OneDrive\שולחן העבודה\My assistant project\venv\Lib\site-packages\telegram\_bot.py", line 703, in _send_message
    result = await self._post(
             ^^^^^^^^^^^^^^^^^
  File "C:\Users\User\OneDrive\שולחן העבודה\My assistant project\venv\Lib\site-packages\telegram\_bot.py", line 613, in _post
    return await self._do_post(
           ^^^^^^^^^^^^^^^^^^^^
  File "C:\Users\User\OneDrive\שולחן העבודה\My assistant project\venv\Lib\site-packages\telegram\ext\_extbot.py", line 340, in _do_post
    return await super()._do_post(
           ^^^^^^^^^^^^^^^^^^^^^^^
  File "C:\Users\User\OneDrive\שולחן העבודה\My assistant project\venv\Lib\site-packages\telegram\_bot.py", line 641, in _do_post
    return await request.post(
           ^^^^^^^^^^^^^^^^^^^
  File "C:\Users\User\OneDrive\שולחן העבודה\My assistant project\venv\Lib\site-packages\telegram\request\_baserequest.py", line 200, in post
    result = await self._request_wrapper(
             ^^^^^^^^^^^^^^^^^^^^^^^^^^^^
  File "C:\Users\User\OneDrive\שולחן העבודה\My assistant project\venv\Lib\site-packages\telegram\request\_baserequest.py", line 379, in _request_wrapper
    raise BadRequest(message)
telegram.error.BadRequest: Message text is empty
2023-12-17 14:24:53,645 - main_logger - INFO - Bot started! Connecting to DB...
2023-12-17 14:24:55,216 - main_logger - INFO - Connected to DB
2023-12-17 14:26:33,536 - clients_logger - DEBUG - {'user_id': 222151854, 'username': 'גוון ויינברגר', 'full_name': 'רומי מזרחי', 'address': 'זום'}
2023-12-17 14:29:22,414 - main_logger - INFO - Bot started! Connecting to DB...
2023-12-17 14:29:24,273 - main_logger - INFO - Connected to DB
2023-12-17 14:36:02,061 - main_logger - INFO - Bot started! Connecting to DB...
2023-12-17 14:36:03,818 - main_logger - INFO - Connected to DB
2023-12-17 14:41:03,549 - main_logger - INFO - Bot started! Connecting to DB...
2023-12-17 14:41:05,174 - main_logger - INFO - Connected to DB
2023-12-17 14:41:33,681 - clients_logger - ERROR - The parameter `inline_keyboard` should be a sequence of sequences of InlineKeyboardButtons
Traceback (most recent call last):
  File "c:\Users\User\OneDrive\שולחן העבודה\My assistant project\my_assistant\clients.py", line 129, in show_clients_callback
    reply_markup = InlineKeyboardMarkup(keyboard)
                   ^^^^^^^^^^^^^^^^^^^^^^^^^^^^^^
  File "C:\Users\User\OneDrive\שולחן העבודה\My assistant project\venv\Lib\site-packages\telegram\_inline\inlinekeyboardmarkup.py", line 79, in __init__
    raise ValueError(
ValueError: The parameter `inline_keyboard` should be a sequence of sequences of InlineKeyboardButtons
2023-12-17 14:42:14,116 - clients_logger - ERROR - The parameter `inline_keyboard` should be a sequence of sequences of InlineKeyboardButtons
Traceback (most recent call last):
  File "c:\Users\User\OneDrive\שולחן העבודה\My assistant project\my_assistant\clients.py", line 129, in show_clients_callback
    reply_markup = InlineKeyboardMarkup(keyboard)
                   ^^^^^^^^^^^^^^^^^^^^^^^^^^^^^^
  File "C:\Users\User\OneDrive\שולחן העבודה\My assistant project\venv\Lib\site-packages\telegram\_inline\inlinekeyboardmarkup.py", line 79, in __init__
    raise ValueError(
ValueError: The parameter `inline_keyboard` should be a sequence of sequences of InlineKeyboardButtons
2023-12-17 14:43:31,693 - main_logger - INFO - Bot started! Connecting to DB...
2023-12-17 14:43:33,566 - main_logger - INFO - Connected to DB
2023-12-18 10:35:44,035 - main_logger - INFO - Bot started! Connecting to DB...
2023-12-18 10:35:45,873 - main_logger - INFO - Connected to DB
2023-12-18 10:58:02,952 - main_logger - INFO - Bot started! Connecting to DB...
2023-12-18 10:58:04,880 - main_logger - INFO - Connected to DB
2023-12-18 10:59:23,953 - main_logger - INFO - Bot started! Connecting to DB...
2023-12-18 10:59:25,727 - main_logger - INFO - Connected to DB
2023-12-18 11:30:34,999 - main_logger - INFO - Bot started! Connecting to DB...
2023-12-18 11:30:36,729 - main_logger - INFO - Connected to DB
2023-12-18 11:30:50,622 - clients_logger - DEBUG - [{'id': 26, 'full_name': 'אגם כהן', 'address': 'זום', 'debt': 0, 'create_time': datetime.datetime(2023, 12, 14, 21, 57, 13), 'user_id': '222151854', 'username': 'גוון ויינברגר'}, {'id': 49, 'full_name': 'אלכסנדרה אהרון', 'address': 'זום', 'debt': 120, 'create_time': datetime.datetime(2023, 12, 17, 10, 26, 5), 'user_id': '222151854', 'username': 'גוון ויינברגר'}, {'id': 30, 'full_name': 'אסף בובק', 'address': 'זום', 'debt': 100, 'create_time': datetime.datetime(2023, 12, 16, 19, 31, 58), 'user_id': '222151854', 'username': 'גוון ויינברגר'}, {'id': 31, 'full_name': 'דביר סולמי', 'address': 'זום', 'debt': 0, 'create_time': datetime.datetime(2023, 12, 16, 19, 32, 56), 'user_id': '222151854', 'username': 'גוון ויינברגר'}, {'id': 37, 'full_name': 'דרור מזרחי', 'address': 'זום', 'debt': 0, 'create_time': datetime.datetime(2023, 12, 16, 19, 38, 13), 'user_id': '222151854', 'username': 'גוון ויינברגר'}, {'id': 36, 'full_name': 'נדב כהן', 'address': 'הדקל 22 לפיד', 'debt': 0, 'create_time': datetime.datetime(2023, 12, 16, 19, 37, 34), 'user_id': '222151854', 'username': 'גוון ויינברגר'}, {'id': 33, 'full_name': 'נועם אפשטיין', 'address': 'הזית 74 לפיד', 'debt': 0, 'create_time': datetime.datetime(2023, 12, 16, 19, 35, 27), 'user_id': '222151854', 'username': 'גוון ויינברגר'}, {'id': 29, 'full_name': 'עדי לוי', 'address': 'שבטי ישראל 17 מודיעין', 'debt': 0, 'create_time': datetime.datetime(2023, 12, 16, 19, 31, 44), 'user_id': '222151854', 'username': 'גוון ויינברגר'}, {'id': 24, 'full_name': 'עדי עזרא', 'address': 'זום', 'debt': 0, 'create_time': datetime.datetime(2023, 12, 14, 16, 52, 45), 'user_id': '222151854', 'username': 'גוון ויינברגר'}, {'id': 32, 'full_name': 'עומרי נוף', 'address': 'זום', 'debt': 0, 'create_time': datetime.datetime(2023, 12, 16, 19, 34, 48), 'user_id': '222151854', 'username': 'גוון ויינברגר'}, {'id': 38, 'full_name': 'עופרי עזרא', 'address': 'זום', 'debt': 0, 'create_time': datetime.datetime(2023, 12, 17, 9, 53, 24), 'user_id': '222151854', 'username': 'גוון ויינברגר'}, {'id': 78, 'full_name': 'רומי מזרחי', 'address': 'זום', 'debt': 0, 'create_time': datetime.datetime(2023, 12, 17, 12, 26, 7), 'user_id': '222151854', 'username': 'גוון ויינברגר'}, {'id': 34, 'full_name': 'שירה זנטי', 'address': 'גורדון 23 נווה שאנן חיפה', 'debt': 0, 'create_time': datetime.datetime(2023, 12, 16, 19, 36, 30), 'user_id': '222151854', 'username': 'גוון ויינברגר'}]
2023-12-18 11:40:06,818 - main_logger - INFO - Bot started! Connecting to DB...
2023-12-18 11:40:08,182 - main_logger - INFO - Connected to DB
2023-12-18 11:40:58,008 - main_logger - INFO - Bot started! Connecting to DB...
2023-12-18 11:40:59,238 - main_logger - INFO - Connected to DB
2023-12-18 13:10:17,173 - main_logger - INFO - Bot started! Connecting to DB...
2023-12-18 13:10:19,016 - main_logger - INFO - Connected to DB
2023-12-18 13:10:51,047 - main_logger - INFO - Bot started! Connecting to DB...
2023-12-18 13:10:52,696 - main_logger - INFO - Connected to DB
2023-12-18 13:14:15,856 - main_logger - INFO - Bot started! Connecting to DB...
2023-12-18 13:14:18,050 - main_logger - INFO - Connected to DB
2023-12-18 13:14:38,329 - db_connection_logger - ERROR - unable to add debt to the client in the data base
2023-12-18 13:14:38,340 - clients_logger - ERROR - 1054 (42S22): Unknown column 'client_id' in 'where clause'
Traceback (most recent call last):
  File "C:\Users\User\OneDrive\שולחן העבודה\My assistant project\venv\Lib\site-packages\mysql\connector\connection_cext.py", line 639, in cmd_query
    self._cmysql.query(
_mysql_connector.MySQLInterfaceError: Unknown column 'client_id' in 'where clause'

The above exception was the direct cause of the following exception:

Traceback (most recent call last):
  File "c:\Users\User\OneDrive\שולחן העבודה\My assistant project\my_assistant\clients.py", line 372, in add_debt
    add_debt_to_db(client_id=client_id, user_id=user_id, debt_to_add=debt)
  File "c:\Users\User\OneDrive\שולחן העבודה\My assistant project\my_assistant\db_connection.py", line 118, in add_debt_to_db
    db_cursor.execute(sql_add_debt, (debt_to_add, client_id, user_id))
  File "C:\Users\User\OneDrive\שולחן העבודה\My assistant project\venv\Lib\site-packages\mysql\connector\cursor_cext.py", line 330, in execute
    result = self._cnx.cmd_query(
             ^^^^^^^^^^^^^^^^^^^^
  File "C:\Users\User\OneDrive\שולחן העבודה\My assistant project\venv\Lib\site-packages\mysql\connector\opentelemetry\context_propagation.py", line 77, in wrapper
    return method(cnx, *args, **kwargs)
           ^^^^^^^^^^^^^^^^^^^^^^^^^^^^
  File "C:\Users\User\OneDrive\שולחן העבודה\My assistant project\venv\Lib\site-packages\mysql\connector\connection_cext.py", line 647, in cmd_query
    raise get_mysql_exception(
mysql.connector.errors.ProgrammingError: 1054 (42S22): Unknown column 'client_id' in 'where clause'
2023-12-18 13:19:29,371 - main_logger - INFO - Bot started! Connecting to DB...
2023-12-18 13:19:30,746 - main_logger - INFO - Connected to DB
2023-12-18 13:19:49,998 - clients_logger - DEBUG - 49
2023-12-18 13:19:50,009 - clients_logger - DEBUG - {'id': 49, 'full_name': 'אלכסנדרה אהרון', 'address': 'זום', 'debt': 0, 'create_time': datetime.datetime(2023, 12, 17, 10, 26, 5), 'user_id': '222151854', 'username': 'גוון ויינברגר'}
2023-12-18 13:19:50,161 - db_connection_logger - ERROR - unable to add debt to the client in the data base
2023-12-18 13:19:50,169 - clients_logger - ERROR - 1054 (42S22): Unknown column 'client_id' in 'where clause'
Traceback (most recent call last):
  File "C:\Users\User\OneDrive\שולחן העבודה\My assistant project\venv\Lib\site-packages\mysql\connector\connection_cext.py", line 639, in cmd_query
    self._cmysql.query(
_mysql_connector.MySQLInterfaceError: Unknown column 'client_id' in 'where clause'

The above exception was the direct cause of the following exception:

Traceback (most recent call last):
  File "c:\Users\User\OneDrive\שולחן העבודה\My assistant project\my_assistant\clients.py", line 376, in add_debt
    add_debt_to_db(client_id=client_id, user_id=user_id, debt_to_add=debt)
  File "c:\Users\User\OneDrive\שולחן העבודה\My assistant project\my_assistant\db_connection.py", line 118, in add_debt_to_db
    db_cursor.execute(sql_add_debt, (debt_to_add, client_id, user_id))
  File "C:\Users\User\OneDrive\שולחן העבודה\My assistant project\venv\Lib\site-packages\mysql\connector\cursor_cext.py", line 330, in execute
    result = self._cnx.cmd_query(
             ^^^^^^^^^^^^^^^^^^^^
  File "C:\Users\User\OneDrive\שולחן העבודה\My assistant project\venv\Lib\site-packages\mysql\connector\opentelemetry\context_propagation.py", line 77, in wrapper
    return method(cnx, *args, **kwargs)
           ^^^^^^^^^^^^^^^^^^^^^^^^^^^^
  File "C:\Users\User\OneDrive\שולחן העבודה\My assistant project\venv\Lib\site-packages\mysql\connector\connection_cext.py", line 647, in cmd_query
    raise get_mysql_exception(
mysql.connector.errors.ProgrammingError: 1054 (42S22): Unknown column 'client_id' in 'where clause'
2023-12-18 13:22:15,105 - main_logger - INFO - Bot started! Connecting to DB...
2023-12-18 13:22:16,819 - main_logger - INFO - Connected to DB
2023-12-18 13:22:39,282 - clients_logger - DEBUG - 49
2023-12-18 13:22:39,283 - clients_logger - DEBUG - {'id': 49, 'full_name': 'אלכסנדרה אהרון', 'address': 'זום', 'debt': 0, 'create_time': datetime.datetime(2023, 12, 17, 10, 26, 5), 'user_id': '222151854', 'username': 'גוון ויינברגר'}
2023-12-18 13:23:15,658 - clients_logger - DEBUG - 32
2023-12-18 13:23:15,660 - clients_logger - DEBUG - {'id': 32, 'full_name': 'עומרי נוף', 'address': 'זום', 'debt': 0, 'create_time': datetime.datetime(2023, 12, 16, 19, 34, 48), 'user_id': '222151854', 'username': 'גוון ויינברגר'}
2023-12-18 13:23:28,533 - clients_logger - DEBUG - 49
2023-12-18 13:23:28,535 - clients_logger - DEBUG - {'id': 49, 'full_name': 'אלכסנדרה אהרון', 'address': 'זום', 'debt': 120, 'create_time': datetime.datetime(2023, 12, 17, 10, 26, 5), 'user_id': '222151854', 'username': 'גוון ויינברגר'}
2023-12-18 13:25:02,091 - main_logger - INFO - Bot started! Connecting to DB...
2023-12-18 13:25:03,987 - main_logger - INFO - Connected to DB
2023-12-18 13:27:11,572 - main_logger - INFO - Bot started! Connecting to DB...
2023-12-18 13:27:13,297 - main_logger - INFO - Connected to DB
2023-12-18 14:54:18,586 - main_logger - INFO - Bot started! Connecting to DB...
2023-12-18 14:54:20,456 - main_logger - INFO - Connected to DB
2023-12-18 14:54:44,595 - clients_logger - ERROR - name 'client_name' is not defined
Traceback (most recent call last):
  File "c:\Users\User\OneDrive\שולחן העבודה\My assistant project\my_assistant\clients.py", line 459, in ask_amount_to_delete
    await update.message.reply_text(f'*ללקוח/ה {client_name} יש חוב של {client_debt}.*\n בחר את הפעולה הרצוייה או לחץ /cancel לביטול',
                                                ^^^^^^^^^^^
NameError: name 'client_name' is not defined. Did you mean: 'client_number'?
2023-12-18 14:55:43,942 - main_logger - INFO - Bot started! Connecting to DB...
2023-12-18 14:55:45,636 - main_logger - INFO - Connected to DB
2023-12-18 14:56:01,469 - db_connection_logger - ERROR - unable to delete debt to the client in the data base
2023-12-18 14:56:01,479 - clients_logger - ERROR - name 'debt_to_add' is not defined
Traceback (most recent call last):
  File "c:\Users\User\OneDrive\שולחן העבודה\My assistant project\my_assistant\clients.py", line 488, in delete_all_debt
    delete_debt_from_db(
  File "c:\Users\User\OneDrive\שולחן העבודה\My assistant project\my_assistant\db_connection.py", line 134, in delete_debt_from_db
    db_cursor.execute(sql_delete_debt, (debt_to_add, client_id, user_id))
                                        ^^^^^^^^^^^
NameError: name 'debt_to_add' is not defined
2023-12-18 14:56:38,745 - main_logger - INFO - Bot started! Connecting to DB...
2023-12-18 14:56:40,007 - main_logger - INFO - Connected to DB
2023-12-18 18:16:28,300 - main_logger - INFO - Bot started! Connecting to DB...
2023-12-18 18:16:31,598 - main_logger - INFO - Connected to DB
2023-12-18 18:35:12,612 - main_logger - INFO - Bot started! Connecting to DB...
2023-12-18 18:35:14,330 - main_logger - INFO - Connected to DB
2023-12-18 18:38:50,323 - clients_logger - ERROR - list index out of range
Traceback (most recent call last):
  File "c:\Users\User\OneDrive\שולחן העבודה\My assistant project\my_assistant\clients.py", line 375, in add_debt
    client_id = (clients_list[client_number_to_add_debt])["id"]
                 ~~~~~~~~~~~~^^^^^^^^^^^^^^^^^^^^^^^^^^^
IndexError: list index out of range
2023-12-18 18:42:08,714 - main_logger - INFO - Bot started! Connecting to DB...
2023-12-18 18:42:10,387 - main_logger - INFO - Connected to DB
2023-12-18 19:10:39,554 - main_logger - INFO - Bot started! Connecting to DB...
2023-12-18 19:10:41,147 - main_logger - INFO - Connected to DB
2023-12-18 19:59:03,614 - main_logger - INFO - Bot started! Connecting to DB...
2023-12-18 19:59:05,236 - main_logger - INFO - Connected to DB
